Workbook
Name switch: #REF!
Name switch: #REF!
Name switch: #REF!
Name achieve: #REF!
Name switch: #REF!
Name switch: #REF!
Name achieve: #REF!
Name switch: #REF!
Name form_income: #REF!
Name achieve: #REF!
Name form_invest: #REF!
Name form_enemy: #REF!
Name achieve: '年間推移シート'!$C$13:$Q$63
Name switch: #REF!
Name switch: #REF!
Name achieve: #REF!
Name achieve: #REF!
Name achieve: #REF!
Name achieve: #REF!
Name switch: #REF!
Name switch: #REF!
Name switch: #REF!
Name achieve: #REF!
Name achieve: #REF!
Name achieve: #REF!
Name switch: #REF!
Name achieve: #REF!
Name achieve: #REF!
Name achieve: #REF!
Name switch: #REF!
Name switch: #REF!

Sheet 説明
F5: 必ずコピーしてお使いください
F7: ①「ファイル」を押す→②「コピーを作成」を押す→③好きな名前に変更して保存
F8: 👈イメージ図はコチラ
F12: 記入例はコチラ
F13: https://docs.google.com/spreadsheets/d/17IY06cKMxbN9RkT_RKE8P9Hi3TCbj9vyqdSf7Ji-IQU/edit?usp=sharing
F16: 使い方ガイドはコチラ | I16: ※1つあたり5分以内の短い動画です（音声を速めて聞くのをオススメします）
F17: ① 家計簿フォーマットの使い方 | H17: https://www.loom.com/share/37b2dd6e3192492cad6bd00e9eec2e59?sid=942f5ea2-309b-4961-a169-0edd331df914
F18: ② 週予算管理の使い方 | H18: https://www.loom.com/share/22315fc3571547b08d7fb8604cdd833b
F19: ③ 年間推移シートの使い方 | H19: https://www.loom.com/share/89c1cf4ee43145dca461fe9334c9dd6f?sid=2a5acbce-cc47-4e1f-b258-f597eeb6d21c
F20: ④ 収支可視化シートの使い方 | H20: https://www.loom.com/share/a11131eea75e4983a4cd70746b292bea?sid=d7ec20dd-8da5-48c0-a97f-9e07cfbbc26d
F21: ⑤ 特別費管理シート＆積立管理シートの使い方 | H21: https://www.loom.com/share/ec77e9ddfe4f4ecdb27c69937ac317c6?sid=0b5f8703-987c-4617-82b4-51dfa63dd329
F22: ⑥ 家計簿フォーマットの印刷方法 | H22: https://www.loom.com/share/468b7c509ef041ecbabe6457f7a6cb27
F23: ⑦ 注意点 | H23: https://www.loom.com/share/fc6dcc39dfc84e028cd50287b05d48bd
F24: ⑧ 支払管理シートの使い方 | H24: https://www.loom.com/share/78292bbc3862419c99e4e5c73a5361a7
F25: ⑨ 変動費明細の追加方法 | H25: https://www.loom.com/share/c84a9fac4d4c455990c32c65b0127334
F26: ⑩ 変動費明細を日付順で並び替える方法 | H26: https://www.loom.com/share/7df2fd3f96d8450eaead1efa6d80f9ae
F27: ⑪ 収入・固定費・変動費・週予算管理の行の追加方法 | H27: https://www.loom.com/share/c5822df7b4aa432da211e2d1040d1c62

Sheet 1月
B1: 1 | D1: ← 年・月を変更するとカレンダーが自動更新されます | J1: ※グレーのセルは自動反映します（入力不要）
B2: 2025 | J2: =DATE(B2,B1,1) -> 45658 | R2: 変動費 明細
B4: 収入 | F4: 先取り貯金・投資 | J4: 月 | K4: 火 | L4: 水 | M4: 木 | N4: 金 | O4: 土 | P4: 日 | R4: 日付 | S4: 週 | T4: 支払方法 | U4: 費目 | V4: 詳細 | X4: 金額 | Y4: 満足度
B5: 費目 | C5: 入金口座 | D5: 金額 | F5: 費目 | G5: 支払方法 | H5: 金額 | J5: =$J$2-weekday($J$2)+2 -> 45656 | K5: =J5+1 -> 45657 | L5: =K5+1 -> 45658 | M5: =L5+1 -> 45659 | N5: =M5+1 -> 45660 | O5: =N5+1 -> 45661 | P5: =O5+1 -> 45662 | R5: 45658 | S5: 1week | T5: 現金 | U5: 🍙 食費 | X5: 1000
B6: 💰 パパ給与 | C6: Ｃ銀行 | D6: 250000 | F6: 💴 貯金 | H6: 20000 | J6: =sumifs($X:$X,$R:$R,J5) -> 0 | K6: =sumifs($X:$X,$R:$R,K5) -> 0 | L6: =sumifs($X:$X,$R:$R,L5) -> 1000 | M6: =sumifs($X:$X,$R:$R,M5) -> 0 | N6: =sumifs($X:$X,$R:$R,N5) -> 0 | O6: =sumifs($X:$X,$R:$R,O5) -> 0 | P6: =sumifs($X:$X,$R:$R,P5) -> 0
B7: 💰 ママ給与 | C7: Ｄ銀行 | D7: 150000 | F7: 💴 NISA | G7: クレカＡ | H7: 30000 | J7: =J5+7 -> 45663 | K7: =K5+7 -> 45664 | L7: =L5+7 -> 45665 | M7: =M5+7 -> 45666 | N7: =N5+7 -> 45667 | O7: =O5+7 -> 45668 | P7: =P5+7 -> 45669
F8: 💴 特別費積み立て | H8: 30000 | J8: =sumifs($X:$X,$R:$R,J7) -> 0 | K8: =sumifs($X:$X,$R:$R,K7) -> 0 | L8: =sumifs($X:$X,$R:$R,L7) -> 0 | M8: =sumifs($X:$X,$R:$R,M7) -> 0 | N8: =sumifs($X:$X,$R:$R,N7) -> 0 | O8: =sumifs($X:$X,$R:$R,O7) -> 0 | P8: =sumifs($X:$X,$R:$R,P7) -> 0
J9: =J7+7 -> 45670 | K9: =K7+7 -> 45671 | L9: =L7+7 -> 45672 | M9: =M7+7 -> 45673 | N9: =N7+7 -> 45674 | O9: =O7+7 -> 45675 | P9: =P7+7 -> 45676
J10: =sumifs($X:$X,$R:$R,J9) -> 0 | K10: =sumifs($X:$X,$R:$R,K9) -> 0 | L10: =sumifs($X:$X,$R:$R,L9) -> 0 | M10: =sumifs($X:$X,$R:$R,M9) -> 0 | N10: =sumifs($X:$X,$R:$R,N9) -> 0 | O10: =sumifs($X:$X,$R:$R,O9) -> 0 | P10: =sumifs($X:$X,$R:$R,P9) -> 0
J11: =J9+7 -> 45677 | K11: =K9+7 -> 45678 | L11: =L9+7 -> 45679 | M11: =M9+7 -> 45680 | N11: =N9+7 -> 45681 | O11: =O9+7 -> 45682 | P11: =P9+7 -> 45683
J12: =sumifs($X:$X,$R:$R,J11) -> 0 | K12: =sumifs($X:$X,$R:$R,K11) -> 0 | L12: =sumifs($X:$X,$R:$R,L11) -> 0 | M12: =sumifs($X:$X,$R:$R,M11) -> 0 | N12: =sumifs($X:$X,$R:$R,N11) -> 0 | O12: =sumifs($X:$X,$R:$R,O11) -> 0 | P12: =sumifs($X:$X,$R:$R,P11) -> 0
J13: =J11+7 -> 45684 | K13: =K11+7 -> 45685 | L13: =L11+7 -> 45686 | M13: =M11+7 -> 45687 | N13: =N11+7 -> 45688 | O13: =O11+7 -> 45689 | P13: =P11+7 -> 45690
B14: 合計 | D14: =SUM(D6:D13) -> 400000 | F14: 合計 | H14: =SUM(H6:H13) -> 80000 | J14: =sumifs($X:$X,$R:$R,J13) -> 0 | K14: =sumifs($X:$X,$R:$R,K13) -> 0 | L14: =sumifs($X:$X,$R:$R,L13) -> 0 | M14: =sumifs($X:$X,$R:$R,M13) -> 0 | N14: =sumifs($X:$X,$R:$R,N13) -> 0 | O14: =sumifs($X:$X,$R:$R,O13) -> 0 | P14: =sumifs($X:$X,$R:$R,P13) -> 0
B16: 支出 | F16: 支出 | J16: 週予算 管理
B17: 固定費 | F17: 変動費
B18: 費目 | C18: 支払方法 | D18: 金額 | F18: 費目 | G18: 予算 | H18: 金額 | J18: 項目 | L18: 1week | O18: 2week
B19: 🏠 住宅 | C19: クレカＡ | D19: 100000 | F19: 🍙 食費 | H19: =sumifs($X:$X,$U:$U,F19) -> 1000 | K19: 予算 | L19: 金額 | M19: 差分 | N19: 予算 | O19: 金額 | P19: 差分
B20: 💡 電気 | C20: クレカＢ | D20: 8000 | F20: 🧴 日用品 | H20: =sumifs($X:$X,$U:$U,F20) -> 0 | J20: 🍙 食費 | K20: 10000 | L20: =sumifs($X:$X,$S:$S,$L$18,$U:$U,J20) -> 1000 | M20: =K20-L20 -> 9000 | O20: =sumifs($X:$X,$S:$S,$O$18,$U:$U,J20) -> 0 | P20: =N20-O20 -> 0
B21: 🔥 ガス | C21: クレカＢ | D21: 5000 | F21: ⛺️ 趣味・娯楽 | H21: =sumifs($X:$X,$U:$U,F21) -> 0 | L21: =sumifs($X:$X,$S:$S,$L$18,$U:$U,J21) -> 0 | M21: =K21-L21 -> 0 | O21: =sumifs($X:$X,$S:$S,$O$18,$U:$U,J21) -> 0 | P21: =N21-O21 -> 0
B22: 🚰 水道 | C22: Ｃ銀行 | D22: 2000 | F22: 🍼 子ども | H22: =sumifs($X:$X,$U:$U,F22) -> 0 | L22: =sumifs($X:$X,$S:$S,$L$18,$U:$U,J22) -> 0 | M22: =K22-L22 -> 0 | O22: =sumifs($X:$X,$S:$S,$O$18,$U:$U,J22) -> 0 | P22: =N22-O22 -> 0
B23: 📱 通信費 | C23: クレカＢ | D23: 5000 | F23: 🏥 健康・医療 | H23: =sumifs($X:$X,$U:$U,F23) -> 0 | L23: =sumifs($X:$X,$S:$S,$L$18,$U:$U,J23) -> 0 | M23: =K23-L23 -> 0 | O23: =sumifs($X:$X,$S:$S,$O$18,$U:$U,J23) -> 0 | P23: =N23-O23 -> 0
B24: 📽️ サブスク | C24: クレカＢ | D24: 2000 | F24: ❓ その他 | H24: =sumifs($X:$X,$U:$U,F24) -> 0 | L24: =sumifs($X:$X,$S:$S,$L$18,$U:$U,J24) -> 0 | M24: =K24-L24 -> 0 | O24: =sumifs($X:$X,$S:$S,$O$18,$U:$U,J24) -> 0 | P24: =N24-O24 -> 0
B25: 📃 保険 | C25: Ｃ銀行 | D25: 5000 | H25: =sumifs($X:$X,$U:$U,F25) -> 0 | L25: =sumifs($X:$X,$S:$S,$L$18,$U:$U,J25) -> 0 | M25: =K25-L25 -> 0 | O25: =sumifs($X:$X,$S:$S,$O$18,$U:$U,J25) -> 0 | P25: =N25-O25 -> 0
B26: 🎓 教養・教育 | C26: Ｄ銀行 | D26: 30000 | H26: =sumifs($X:$X,$U:$U,F26) -> 0 | L26: =sumifs($X:$X,$S:$S,$L$18,$U:$U,J26) -> 0 | M26: =K26-L26 -> 0 | O26: =sumifs($X:$X,$S:$S,$O$18,$U:$U,J26) -> 0 | P26: =N26-O26 -> 0
H27: =sumifs($X:$X,$U:$U,F27) -> 0 | J27: ALL | K27: =SUM(K20:K26) -> 10000 | L27: =SUM(L20:L26) -> 1000 | M27: =K27-L27 -> 9000 | N27: =SUM(N20:N26) -> 0 | O27: =SUM(O20:O26) -> 0 | P27: =N27-O27 -> 0
H28: =sumifs($X:$X,$U:$U,F28) -> 0
H29: =sumifs($X:$X,$U:$U,F29) -> 0 | J29: 項目 | L29: 3week | O29: 4week
H30: =sumifs($X:$X,$U:$U,F30) -> 0 | K30: 予算 | L30: 金額 | M30: 差分 | N30: 予算 | O30: 金額 | P30: 差分
B31: 合計 | D31: =SUM(D19:D30) -> 157000 | F31: 合計 | G31: =SUM(G19:G30) -> 0 | H31: =SUM(H19:H30) -> 1000 | L31: =sumifs($X:$X,$S:$S,$L$29,$U:$U,J31) -> 0 | M31: =K31-L31 -> 0 | O31: =sumifs($X:$X,$S:$S,$O$29,$U:$U,J31) -> 0 | P31: =N31-O31 -> 0
L32: =sumifs($X:$X,$S:$S,$L$29,$U:$U,J32) -> 0 | M32: =K32-L32 -> 0 | O32: =sumifs($X:$X,$S:$S,$O$29,$U:$U,J32) -> 0 | P32: =N32-O32 -> 0
B33: 特別費 | F33: 今月の収支 | H33: 金額 | L33: =sumifs($X:$X,$S:$S,$L$29,$U:$U,J33) -> 0 | M33: =K33-L33 -> 0 | O33: =sumifs($X:$X,$S:$S,$O$29,$U:$U,J33) -> 0 | P33: =N33-O33 -> 0
B34: 費目 | C34: 支払方法 | D34: 金額 | F34: 収入（a） | H34: =D14 -> 400000 | L34: =sumifs($X:$X,$S:$S,$L$29,$U:$U,J34) -> 0 | M34: =K34-L34 -> 0 | O34: =sumifs($X:$X,$S:$S,$O$29,$U:$U,J34) -> 0 | P34: =N34-O34 -> 0
B35: 🍴 食事 | C35: クレカＢ | D35: 12000 | F35: 先取り貯金・投資（b） | H35: =H14 -> 80000 | L35: =sumifs($X:$X,$S:$S,$L$29,$U:$U,J35) -> 0 | M35: =K35-L35 -> 0 | O35: =sumifs($X:$X,$S:$S,$O$29,$U:$U,J35) -> 0 | P35: =N35-O35 -> 0
F36: 支出（c） | H36: =D31+H31 -> 158000 | L36: =sumifs($X:$X,$S:$S,$L$29,$U:$U,J36) -> 0 | M36: =K36-L36 -> 0 | O36: =sumifs($X:$X,$S:$S,$O$29,$U:$U,J36) -> 0 | P36: =N36-O36 -> 0
F37: 余り貯金（d）※a-b-c | H37: =H34-H35-H36 -> 162000 | L37: =sumifs($X:$X,$S:$S,$L$29,$U:$U,J37) -> 0 | M37: =K37-L37 -> 0 | O37: =sumifs($X:$X,$S:$S,$O$29,$U:$U,J37) -> 0 | P37: =N37-O37 -> 0
F38: 貯蓄合計（e）※b+d | H38: =H35+H37 -> 242000 | J38: ALL | K38: =SUM(K31:K37) -> 0 | L38: =SUM(L31:L37) -> 0 | M38: =K38-L38 -> 0 | N38: =SUM(N31:N37) -> 0 | O38: =SUM(O31:O37) -> 0 | P38: =N38-O38 -> 0
F40: 支出率（c/a)×100 | G40: 貯蓄率 （e/a)×100 | J40: 項目 | L40: 5week | O40: ALL
F41: =H36/H34 -> 0.395 | G41: =H38/H34 -> 0.605 | K41: 予算 | L41: 金額 | M41: 差分 | N41: 予算 | O41: 金額 | P41: 差分
B42: 合計 | D42: =SUM(D35:D41) -> 12000 | L42: =sumifs($X:$X,$S:$S,$L$40,$U:$U,J42) -> 0 | M42: =K42-L42 -> 0 | N42: =K20+N20+K31+N31+K42 -> 10000 | O42: =L20+O20+L31+O31+L42 -> 1000 | P42: =N42-O42 -> 9000
D43: ※収支の計算外 | F43: ※目標：80%以下 | H43: ※目標：20%以上 | L43: =sumifs($X:$X,$S:$S,$L$40,$U:$U,J43) -> 0 | M43: =K43-L43 -> 0 | N43: =K21+N21+K32+N32+K43 -> 0 | O43: =L21+O21+L32+O32+L43 -> 0 | P43: =N43-O43 -> 0
...

Sheet 2月
B1: 2 | D1: ← 年・月を変更するとカレンダーが自動更新されます | J1: ※グレーのセルは自動反映します（入力不要）
B2: 2025 | J2: =DATE(B2,B1,1) -> 45689 | R2: 変動費 明細
B4: 収入 | F4: 先取り貯金・投資 | J4: 月 | K4: 火 | L4: 水 | M4: 木 | N4: 金 | O4: 土 | P4: 日 | R4: 日付 | S4: 週 | T4: 支払方法 | U4: 費目 | V4: 詳細 | X4: 金額 | Y4: 満足度
B5: 費目 | C5: 入金口座 | D5: 金額 | F5: 費目 | G5: 支払方法 | H5: 金額 | J5: =$J$2-weekday($J$2)+2 -> 45684 | K5: =J5+1 -> 45685 | L5: =K5+1 -> 45686 | M5: =L5+1 -> 45687 | N5: =M5+1 -> 45688 | O5: =N5+1 -> 45689 | P5: =O5+1 -> 45690 | R5: 45689
J6: =sumifs($X:$X,$R:$R,J5) -> 0 | K6: =sumifs($X:$X,$R:$R,K5) -> 0 | L6: =sumifs($X:$X,$R:$R,L5) -> 0 | M6: =sumifs($X:$X,$R:$R,M5) -> 0 | N6: =sumifs($X:$X,$R:$R,N5) -> 0 | O6: =sumifs($X:$X,$R:$R,O5) -> 0 | P6: =sumifs($X:$X,$R:$R,P5) -> 0
J7: =J5+7 -> 45691 | K7: =K5+7 -> 45692 | L7: =L5+7 -> 45693 | M7: =M5+7 -> 45694 | N7: =N5+7 -> 45695 | O7: =O5+7 -> 45696 | P7: =P5+7 -> 45697
J8: =sumifs($X:$X,$R:$R,J7) -> 0 | K8: =sumifs($X:$X,$R:$R,K7) -> 0 | L8: =sumifs($X:$X,$R:$R,L7) -> 0 | M8: =sumifs($X:$X,$R:$R,M7) -> 0 | N8: =sumifs($X:$X,$R:$R,N7) -> 0 | O8: =sumifs($X:$X,$R:$R,O7) -> 0 | P8: =sumifs($X:$X,$R:$R,P7) -> 0
J9: =J7+7 -> 45698 | K9: =K7+7 -> 45699 | L9: =L7+7 -> 45700 | M9: =M7+7 -> 45701 | N9: =N7+7 -> 45702 | O9: =O7+7 -> 45703 | P9: =P7+7 -> 45704
J10: =sumifs($X:$X,$R:$R,J9) -> 0 | K10: =sumifs($X:$X,$R:$R,K9) -> 0 | L10: =sumifs($X:$X,$R:$R,L9) -> 0 | M10: =sumifs($X:$X,$R:$R,M9) -> 0 | N10: =sumifs($X:$X,$R:$R,N9) -> 0 | O10: =sumifs($X:$X,$R:$R,O9) -> 0 | P10: =sumifs($X:$X,$R:$R,P9) -> 0
J11: =J9+7 -> 45705 | K11: =K9+7 -> 45706 | L11: =L9+7 -> 45707 | M11: =M9+7 -> 45708 | N11: =N9+7 -> 45709 | O11: =O9+7 -> 45710 | P11: =P9+7 -> 45711
J12: =sumifs($X:$X,$R:$R,J11) -> 0 | K12: =sumifs($X:$X,$R:$R,K11) -> 0 | L12: =sumifs($X:$X,$R:$R,L11) -> 0 | M12: =sumifs($X:$X,$R:$R,M11) -> 0 | N12: =sumifs($X:$X,$R:$R,N11) -> 0 | O12: =sumifs($X:$X,$R:$R,O11) -> 0 | P12: =sumifs($X:$X,$R:$R,P11) -> 0
J13: =J11+7 -> 45712 | K13: =K11+7 -> 45713 | L13: =L11+7 -> 45714 | M13: =M11+7 -> 45715 | N13: =N11+7 -> 45716 | O13: =O11+7 -> 45717 | P13: =P11+7 -> 45718
B14: 合計 | D14: =SUM(D6:D13) -> 0 | F14: 合計 | H14: =SUM(H6:H13) -> 0 | J14: =sumifs($X:$X,$R:$R,J13) -> 0 | K14: =sumifs($X:$X,$R:$R,K13) -> 0 | L14: =sumifs($X:$X,$R:$R,L13) -> 0 | M14: =sumifs($X:$X,$R:$R,M13) -> 0 | N14: =sumifs($X:$X,$R:$R,N13) -> 0 | O14: =sumifs($X:$X,$R:$R,O13) -> 0 | P14: =sumifs($X:$X,$R:$R,P13) -> 0
B16: 支出 | F16: 支出 | J16: 週予算 管理
B17: 固定費 | F17: 変動費
B18: 費目 | C18: 支払方法 | D18: 金額 | F18: 費目 | G18: 予算 | H18: 金額 | J18: 項目 | L18: 1week | O18: 2week
H19: =sumifs($X:$X,$U:$U,F19) -> 0 | K19: 予算 | L19: 金額 | M19: 差分 | N19: 予算 | O19: 金額 | P19: 差分
H20: =sumifs($X:$X,$U:$U,F20) -> 0 | L20: =sumifs($X:$X,$S:$S,$L$18,$U:$U,J20) -> 0 | M20: =K20-L20 -> 0 | O20: =sumifs($X:$X,$S:$S,$O$18,$U:$U,J20) -> 0 | P20: =N20-O20 -> 0
H21: =sumifs($X:$X,$U:$U,F21) -> 0 | L21: =sumifs($X:$X,$S:$S,$L$18,$U:$U,J21) -> 0 | M21: =K21-L21 -> 0 | O21: =sumifs($X:$X,$S:$S,$O$18,$U:$U,J21) -> 0 | P21: =N21-O21 -> 0
H22: =sumifs($X:$X,$U:$U,F22) -> 0 | L22: =sumifs($X:$X,$S:$S,$L$18,$U:$U,J22) -> 0 | M22: =K22-L22 -> 0 | O22: =sumifs($X:$X,$S:$S,$O$18,$U:$U,J22) -> 0 | P22: =N22-O22 -> 0
H23: =sumifs($X:$X,$U:$U,F23) -> 0 | L23: =sumifs($X:$X,$S:$S,$L$18,$U:$U,J23) -> 0 | M23: =K23-L23 -> 0 | O23: =sumifs($X:$X,$S:$S,$O$18,$U:$U,J23) -> 0 | P23: =N23-O23 -> 0
H24: =sumifs($X:$X,$U:$U,F24) -> 0 | L24: =sumifs($X:$X,$S:$S,$L$18,$U:$U,J24) -> 0 | M24: =K24-L24 -> 0 | O24: =sumifs($X:$X,$S:$S,$O$18,$U:$U,J24) -> 0 | P24: =N24-O24 -> 0
H25: =sumifs($X:$X,$U:$U,F25) -> 0 | L25: =sumifs($X:$X,$S:$S,$L$18,$U:$U,J25) -> 0 | M25: =K25-L25 -> 0 | O25: =sumifs($X:$X,$S:$S,$O$18,$U:$U,J25) -> 0 | P25: =N25-O25 -> 0
H26: =sumifs($X:$X,$U:$U,F26) -> 0 | L26: =sumifs($X:$X,$S:$S,$L$18,$U:$U,J26) -> 0 | M26: =K26-L26 -> 0 | O26: =sumifs($X:$X,$S:$S,$O$18,$U:$U,J26) -> 0 | P26: =N26-O26 -> 0
H27: =sumifs($X:$X,$U:$U,F27) -> 0 | J27: ALL | K27: =SUM(K20:K26) -> 0 | L27: =SUM(L20:L26) -> 0 | M27: =K27-L27 -> 0 | N27: =SUM(N20:N26) -> 0 | O27: =SUM(O20:O26) -> 0 | P27: =N27-O27 -> 0
H28: =sumifs($X:$X,$U:$U,F28) -> 0
H29: =sumifs($X:$X,$U:$U,F29) -> 0 | J29: 項目 | L29: 3week | O29: 4week
H30: =sumifs($X:$X,$U:$U,F30) -> 0 | K30: 予算 | L30: 金額 | M30: 差分 | N30: 予算 | O30: 金額 | P30: 差分
B31: 合計 | D31: =SUM(D19:D30) -> 0 | F31: 合計 | G31: =SUM(G19:G30) -> 0 | H31: =SUM(H19:H30) -> 0 | L31: =sumifs($X:$X,$S:$S,$L$29,$U:$U,J31) -> 0 | M31: =K31-L31 -> 0 | O31: =sumifs($X:$X,$S:$S,$O$29,$U:$U,J31) -> 0 | P31: =N31-O31 -> 0
L32: =sumifs($X:$X,$S:$S,$L$29,$U:$U,J32) -> 0 | M32: =K32-L32 -> 0 | O32: =sumifs($X:$X,$S:$S,$O$29,$U:$U,J32) -> 0 | P32: =N32-O32 -> 0
B33: 特別費 | F33: 今月の収支 | H33: 金額 | L33: =sumifs($X:$X,$S:$S,$L$29,$U:$U,J33) -> 0 | M33: =K33-L33 -> 0 | O33: =sumifs($X:$X,$S:$S,$O$29,$U:$U,J33) -> 0 | P33: =N33-O33 -> 0
B34: 費目 | C34: 支払方法 | D34: 金額 | F34: 収入（a） | H34: =D14 -> 0 | L34: =sumifs($X:$X,$S:$S,$L$29,$U:$U,J34) -> 0 | M34: =K34-L34 -> 0 | O34: =sumifs($X:$X,$S:$S,$O$29,$U:$U,J34) -> 0 | P34: =N34-O34 -> 0
F35: 先取り貯金・投資（b） | H35: =H14 -> 0 | L35: =sumifs($X:$X,$S:$S,$L$29,$U:$U,J35) -> 0 | M35: =K35-L35 -> 0 | O35: =sumifs($X:$X,$S:$S,$O$29,$U:$U,J35) -> 0 | P35: =N35-O35 -> 0
F36: 支出（c） | H36: =D31+H31 -> 0 | L36: =sumifs($X:$X,$S:$S,$L$29,$U:$U,J36) -> 0 | M36: =K36-L36 -> 0 | O36: =sumifs($X:$X,$S:$S,$O$29,$U:$U,J36) -> 0 | P36: =N36-O36 -> 0
F37: 余り貯金（d）※a-b-c | H37: =H34-H35-H36 -> 0 | L37: =sumifs($X:$X,$S:$S,$L$29,$U:$U,J37) -> 0 | M37: =K37-L37 -> 0 | O37: =sumifs($X:$X,$S:$S,$O$29,$U:$U,J37) -> 0 | P37: =N37-O37 -> 0
F38: 貯蓄合計（e）※b+d | H38: =H35+H37 -> 0 | J38: ALL | K38: =SUM(K31:K37) -> 0 | L38: =SUM(L31:L37) -> 0 | M38: =K38-L38 -> 0 | N38: =SUM(N31:N37) -> 0 | O38: =SUM(O31:O37) -> 0 | P38: =N38-O38 -> 0
F40: 支出率（c/a)×100 | G40: 貯蓄率 （e/a)×100 | J40: 項目 | L40: 5week | O40: ALL
F41: =H36/H34 -> #DIV/0! | G41: =H38/H34 -> #DIV/0! | K41: 予算 | L41: 金額 | M41: 差分 | N41: 予算 | O41: 金額 | P41: 差分
B42: 合計 | D42: =SUM(D35:D41) -> 0 | L42: =sumifs($X:$X,$S:$S,$L$40,$U:$U,J42) -> 0 | M42: =K42-L42 -> 0 | N42: =K20+N20+K31+N31+K42 -> 0 | O42: =L20+O20+L31+O31+L42 -> 0 | P42: =N42-O42 -> 0
D43: ※収支の計算外 | F43: ※目標：80%以下 | H43: ※目標：20%以上 | L43: =sumifs($X:$X,$S:$S,$L$40,$U:$U,J43) -> 0 | M43: =K43-L43 -> 0 | N43: =K21+N21+K32+N32+K43 -> 0 | O43: =L21+O21+L32+O32+L43 -> 0 | P43: =N43-O43 -> 0
...

Sheet 3月
B1: 3 | D1: ← 年・月を変更するとカレンダーが自動更新されます | J1: ※グレーのセルは自動反映します（入力不要）
B2: 2025 | J2: =DATE(B2,B1,1) -> 45717 | R2: 変動費 明細
B4: 収入 | F4: 先取り貯金・投資 | J4: 月 | K4: 火 | L4: 水 | M4: 木 | N4: 金 | O4: 土 | P4: 日 | R4: 日付 | S4: 週 | T4: 支払方法 | U4: 費目 | V4: 詳細 | X4: 金額 | Y4: 満足度
B5: 費目 | C5: 入金口座 | D5: 金額 | F5: 費目 | G5: 支払方法 | H5: 金額 | J5: =$J$2-weekday($J$2)+2 -> 45712 | K5: =J5+1 -> 45713 | L5: =K5+1 -> 45714 | M5: =L5+1 -> 45715 | N5: =M5+1 -> 45716 | O5: =N5+1 -> 45717 | P5: =O5+1 -> 45718 | R5: 45717
J6: =sumifs($X:$X,$R:$R,J5) -> 0 | K6: =sumifs($X:$X,$R:$R,K5) -> 0 | L6: =sumifs($X:$X,$R:$R,L5) -> 0 | M6: =sumifs($X:$X,$R:$R,M5) -> 0 | N6: =sumifs($X:$X,$R:$R,N5) -> 0 | O6: =sumifs($X:$X,$R:$R,O5) -> 0 | P6: =sumifs($X:$X,$R:$R,P5) -> 0
J7: =J5+7 -> 45719 | K7: =K5+7 -> 45720 | L7: =L5+7 -> 45721 | M7: =M5+7 -> 45722 | N7: =N5+7 -> 45723 | O7: =O5+7 -> 45724 | P7: =P5+7 -> 45725
J8: =sumifs($X:$X,$R:$R,J7) -> 0 | K8: =sumifs($X:$X,$R:$R,K7) -> 0 | L8: =sumifs($X:$X,$R:$R,L7) -> 0 | M8: =sumifs($X:$X,$R:$R,M7) -> 0 | N8: =sumifs($X:$X,$R:$R,N7) -> 0 | O8: =sumifs($X:$X,$R:$R,O7) -> 0 | P8: =sumifs($X:$X,$R:$R,P7) -> 0
J9: =J7+7 -> 45726 | K9: =K7+7 -> 45727 | L9: =L7+7 -> 45728 | M9: =M7+7 -> 45729 | N9: =N7+7 -> 45730 | O9: =O7+7 -> 45731 | P9: =P7+7 -> 45732
J10: =sumifs($X:$X,$R:$R,J9) -> 0 | K10: =sumifs($X:$X,$R:$R,K9) -> 0 | L10: =sumifs($X:$X,$R:$R,L9) -> 0 | M10: =sumifs($X:$X,$R:$R,M9) -> 0 | N10: =sumifs($X:$X,$R:$R,N9) -> 0 | O10: =sumifs($X:$X,$R:$R,O9) -> 0 | P10: =sumifs($X:$X,$R:$R,P9) -> 0
J11: =J9+7 -> 45733 | K11: =K9+7 -> 45734 | L11: =L9+7 -> 45735 | M11: =M9+7 -> 45736 | N11: =N9+7 -> 45737 | O11: =O9+7 -> 45738 | P11: =P9+7 -> 45739
J12: =sumifs($X:$X,$R:$R,J11) -> 0 | K12: =sumifs($X:$X,$R:$R,K11) -> 0 | L12: =sumifs($X:$X,$R:$R,L11) -> 0 | M12: =sumifs($X:$X,$R:$R,M11) -> 0 | N12: =sumifs($X:$X,$R:$R,N11) -> 0 | O12: =sumifs($X:$X,$R:$R,O11) -> 0 | P12: =sumifs($X:$X,$R:$R,P11) -> 0
J13: =J11+7 -> 45740 | K13: =K11+7 -> 45741 | L13: =L11+7 -> 45742 | M13: =M11+7 -> 45743 | N13: =N11+7 -> 45744 | O13: =O11+7 -> 45745 | P13: =P11+7 -> 45746
B14: 合計 | D14: =SUM(D6:D13) -> 0 | F14: 合計 | H14: =SUM(H6:H13) -> 0 | J14: =sumifs($X:$X,$R:$R,J13) -> 0 | K14: =sumifs($X:$X,$R:$R,K13) -> 0 | L14: =sumifs($X:$X,$R:$R,L13) -> 0 | M14: =sumifs($X:$X,$R:$R,M13) -> 0 | N14: =sumifs($X:$X,$R:$R,N13) -> 0 | O14: =sumifs($X:$X,$R:$R,O13) -> 0 | P14: =sumifs($X:$X,$R:$R,P13) -> 0
B16: 支出 | F16: 支出 | J16: 週予算 管理
B17: 固定費 | F17: 変動費
B18: 費目 | C18: 支払方法 | D18: 金額 | F18: 費目 | G18: 予算 | H18: 金額 | J18: 項目 | L18: 1week | O18: 2week
H19: =sumifs($X:$X,$U:$U,F19) -> 0 | K19: 予算 | L19: 金額 | M19: 差分 | N19: 予算 | O19: 金額 | P19: 差分
H20: =sumifs($X:$X,$U:$U,F20) -> 0 | L20: =sumifs($X:$X,$S:$S,$L$18,$U:$U,J20) -> 0 | M20: =K20-L20 -> 0 | O20: =sumifs($X:$X,$S:$S,$O$18,$U:$U,J20) -> 0 | P20: =N20-O20 -> 0
H21: =sumifs($X:$X,$U:$U,F21) -> 0 | L21: =sumifs($X:$X,$S:$S,$L$18,$U:$U,J21) -> 0 | M21: =K21-L21 -> 0 | O21: =sumifs($X:$X,$S:$S,$O$18,$U:$U,J21) -> 0 | P21: =N21-O21 -> 0
H22: =sumifs($X:$X,$U:$U,F22) -> 0 | L22: =sumifs($X:$X,$S:$S,$L$18,$U:$U,J22) -> 0 | M22: =K22-L22 -> 0 | O22: =sumifs($X:$X,$S:$S,$O$18,$U:$U,J22) -> 0 | P22: =N22-O22 -> 0
H23: =sumifs($X:$X,$U:$U,F23) -> 0 | L23: =sumifs($X:$X,$S:$S,$L$18,$U:$U,J23) -> 0 | M23: =K23-L23 -> 0 | O23: =sumifs($X:$X,$S:$S,$O$18,$U:$U,J23) -> 0 | P23: =N23-O23 -> 0
H24: =sumifs($X:$X,$U:$U,F24) -> 0 | L24: =sumifs($X:$X,$S:$S,$L$18,$U:$U,J24) -> 0 | M24: =K24-L24 -> 0 | O24: =sumifs($X:$X,$S:$S,$O$18,$U:$U,J24) -> 0 | P24: =N24-O24 -> 0
H25: =sumifs($X:$X,$U:$U,F25) -> 0 | L25: =sumifs($X:$X,$S:$S,$L$18,$U:$U,J25) -> 0 | M25: =K25-L25 -> 0 | O25: =sumifs($X:$X,$S:$S,$O$18,$U:$U,J25) -> 0 | P25: =N25-O25 -> 0
H26: =sumifs($X:$X,$U:$U,F26) -> 0 | L26: =sumifs($X:$X,$S:$S,$L$18,$U:$U,J26) -> 0 | M26: =K26-L26 -> 0 | O26: =sumifs($X:$X,$S:$S,$O$18,$U:$U,J26) -> 0 | P26: =N26-O26 -> 0
H27: =sumifs($X:$X,$U:$U,F27) -> 0 | J27: ALL | K27: =SUM(K20:K26) -> 0 | L27: =SUM(L20:L26) -> 0 | M27: =K27-L27 -> 0 | N27: =SUM(N20:N26) -> 0 | O27: =SUM(O20:O26) -> 0 | P27: =N27-O27 -> 0
H28: =sumifs($X:$X,$U:$U,F28) -> 0
H29: =sumifs($X:$X,$U:$U,F29) -> 0 | J29: 項目 | L29: 3week | O29: 4week
H30: =sumifs($X:$X,$U:$U,F30) -> 0 | K30: 予算 | L30: 金額 | M30: 差分 | N30: 予算 | O30: 金額 | P30: 差分
B31: 合計 | D31: =SUM(D19:D30) -> 0 | F31: 合計 | G31: =SUM(G19:G30) -> 0 | H31: =SUM(H19:H30) -> 0 | L31: =sumifs($X:$X,$S:$S,$L$29,$U:$U,J31) -> 0 | M31: =K31-L31 -> 0 | O31: =sumifs($X:$X,$S:$S,$O$29,$U:$U,J31) -> 0 | P31: =N31-O31 -> 0
L32: =sumifs($X:$X,$S:$S,$L$29,$U:$U,J32) -> 0 | M32: =K32-L32 -> 0 | O32: =sumifs($X:$X,$S:$S,$O$29,$U:$U,J32) -> 0 | P32: =N32-O32 -> 0
B33: 特別費 | F33: 今月の収支 | H33: 金額 | L33: =sumifs($X:$X,$S:$S,$L$29,$U:$U,J33) -> 0 | M33: =K33-L33 -> 0 | O33: =sumifs($X:$X,$S:$S,$O$29,$U:$U,J33) -> 0 | P33: =N33-O33 -> 0
B34: 費目 | C34: 支払方法 | D34: 金額 | F34: 収入（a） | H34: =D14 -> 0 | L34: =sumifs($X:$X,$S:$S,$L$29,$U:$U,J34) -> 0 | M34: =K34-L34 -> 0 | O34: =sumifs($X:$X,$S:$S,$O$29,$U:$U,J34) -> 0 | P34: =N34-O34 -> 0
F35: 先取り貯金・投資（b） | H35: =H14 -> 0 | L35: =sumifs($X:$X,$S:$S,$L$29,$U:$U,J35) -> 0 | M35: =K35-L35 -> 0 | O35: =sumifs($X:$X,$S:$S,$O$29,$U:$U,J35) -> 0 | P35: =N35-O35 -> 0
F36: 支出（c） | H36: =D31+H31 -> 0 | L36: =sumifs($X:$X,$S:$S,$L$29,$U:$U,J36) -> 0 | M36: =K36-L36 -> 0 | O36: =sumifs($X:$X,$S:$S,$O$29,$U:$U,J36) -> 0 | P36: =N36-O36 -> 0
F37: 余り貯金（d）※a-b-c | H37: =H34-H35-H36 -> 0 | L37: =sumifs($X:$X,$S:$S,$L$29,$U:$U,J37) -> 0 | M37: =K37-L37 -> 0 | O37: =sumifs($X:$X,$S:$S,$O$29,$U:$U,J37) -> 0 | P37: =N37-O37 -> 0
F38: 貯蓄合計（e）※b+d | H38: =H35+H37 -> 0 | J38: ALL | K38: =SUM(K31:K37) -> 0 | L38: =SUM(L31:L37) -> 0 | M38: =K38-L38 -> 0 | N38: =SUM(N31:N37) -> 0 | O38: =SUM(O31:O37) -> 0 | P38: =N38-O38 -> 0
F40: 支出率（c/a)×100 | G40: 貯蓄率 （e/a)×100 | J40: 項目 | L40: 5week | O40: ALL
F41: =H36/H34 -> #DIV/0! | G41: =H38/H34 -> #DIV/0! | K41: 予算 | L41: 金額 | M41: 差分 | N41: 予算 | O41: 金額 | P41: 差分
B42: 合計 | D42: =SUM(D35:D41) -> 0 | L42: =sumifs($X:$X,$S:$S,$L$40,$U:$U,J42) -> 0 | M42: =K42-L42 -> 0 | N42: =K20+N20+K31+N31+K42 -> 0 | O42: =L20+O20+L31+O31+L42 -> 0 | P42: =N42-O42 -> 0
D43: ※収支の計算外 | F43: ※目標：80%以下 | H43: ※目標：20%以上 | L43: =sumifs($X:$X,$S:$S,$L$40,$U:$U,J43) -> 0 | M43: =K43-L43 -> 0 | N43: =K21+N21+K32+N32+K43 -> 0 | O43: =L21+O21+L32+O32+L43 -> 0 | P43: =N43-O43 -> 0
...

Sheet 4月
B1: 4 | D1: ← 年・月を変更するとカレンダーが自動更新されます | J1: ※グレーのセルは自動反映します（入力不要）
B2: 2025 | J2: =DATE(B2,B1,1) -> 45748 | R2: 変動費 明細
B4: 収入 | F4: 先取り貯金・投資 | J4: 月 | K4: 火 | L4: 水 | M4: 木 | N4: 金 | O4: 土 | P4: 日 | R4: 日付 | S4: 週 | T4: 支払方法 | U4: 費目 | V4: 詳細 | X4: 金額 | Y4: 満足度
B5: 費目 | C5: 入金口座 | D5: 金額 | F5: 費目 | G5: 支払方法 | H5: 金額 | J5: =$J$2-weekday($J$2)+2 -> 45747 | K5: =J5+1 -> 45748 | L5: =K5+1 -> 45749 | M5: =L5+1 -> 45750 | N5: =M5+1 -> 45751 | O5: =N5+1 -> 45752 | P5: =O5+1 -> 45753 | R5: 45748
J6: =sumifs($X:$X,$R:$R,J5) -> 0 | K6: =sumifs($X:$X,$R:$R,K5) -> 0 | L6: =sumifs($X:$X,$R:$R,L5) -> 0 | M6: =sumifs($X:$X,$R:$R,M5) -> 0 | N6: =sumifs($X:$X,$R:$R,N5) -> 0 | O6: =sumifs($X:$X,$R:$R,O5) -> 0 | P6: =sumifs($X:$X,$R:$R,P5) -> 0
J7: =J5+7 -> 45754 | K7: =K5+7 -> 45755 | L7: =L5+7 -> 45756 | M7: =M5+7 -> 45757 | N7: =N5+7 -> 45758 | O7: =O5+7 -> 45759 | P7: =P5+7 -> 45760
J8: =sumifs($X:$X,$R:$R,J7) -> 0 | K8: =sumifs($X:$X,$R:$R,K7) -> 0 | L8: =sumifs($X:$X,$R:$R,L7) -> 0 | M8: =sumifs($X:$X,$R:$R,M7) -> 0 | N8: =sumifs($X:$X,$R:$R,N7) -> 0 | O8: =sumifs($X:$X,$R:$R,O7) -> 0 | P8: =sumifs($X:$X,$R:$R,P7) -> 0
J9: =J7+7 -> 45761 | K9: =K7+7 -> 45762 | L9: =L7+7 -> 45763 | M9: =M7+7 -> 45764 | N9: =N7+7 -> 45765 | O9: =O7+7 -> 45766 | P9: =P7+7 -> 45767
J10: =sumifs($X:$X,$R:$R,J9) -> 0 | K10: =sumifs($X:$X,$R:$R,K9) -> 0 | L10: =sumifs($X:$X,$R:$R,L9) -> 0 | M10: =sumifs($X:$X,$R:$R,M9) -> 0 | N10: =sumifs($X:$X,$R:$R,N9) -> 0 | O10: =sumifs($X:$X,$R:$R,O9) -> 0 | P10: =sumifs($X:$X,$R:$R,P9) -> 0
J11: =J9+7 -> 45768 | K11: =K9+7 -> 45769 | L11: =L9+7 -> 45770 | M11: =M9+7 -> 45771 | N11: =N9+7 -> 45772 | O11: =O9+7 -> 45773 | P11: =P9+7 -> 45774
J12: =sumifs($X:$X,$R:$R,J11) -> 0 | K12: =sumifs($X:$X,$R:$R,K11) -> 0 | L12: =sumifs($X:$X,$R:$R,L11) -> 0 | M12: =sumifs($X:$X,$R:$R,M11) -> 0 | N12: =sumifs($X:$X,$R:$R,N11) -> 0 | O12: =sumifs($X:$X,$R:$R,O11) -> 0 | P12: =sumifs($X:$X,$R:$R,P11) -> 0
J13: =J11+7 -> 45775 | K13: =K11+7 -> 45776 | L13: =L11+7 -> 45777 | M13: =M11+7 -> 45778 | N13: =N11+7 -> 45779 | O13: =O11+7 -> 45780 | P13: =P11+7 -> 45781
B14: 合計 | D14: =SUM(D6:D13) -> 0 | F14: 合計 | H14: =SUM(H6:H13) -> 0 | J14: =sumifs($X:$X,$R:$R,J13) -> 0 | K14: =sumifs($X:$X,$R:$R,K13) -> 0 | L14: =sumifs($X:$X,$R:$R,L13) -> 0 | M14: =sumifs($X:$X,$R:$R,M13) -> 0 | N14: =sumifs($X:$X,$R:$R,N13) -> 0 | O14: =sumifs($X:$X,$R:$R,O13) -> 0 | P14: =sumifs($X:$X,$R:$R,P13) -> 0
B16: 支出 | F16: 支出 | J16: 週予算 管理
B17: 固定費 | F17: 変動費
B18: 費目 | C18: 支払方法 | D18: 金額 | F18: 費目 | G18: 予算 | H18: 金額 | J18: 項目 | L18: 1week | O18: 2week
H19: =sumifs($X:$X,$U:$U,F19) -> 0 | K19: 予算 | L19: 金額 | M19: 差分 | N19: 予算 | O19: 金額 | P19: 差分
H20: =sumifs($X:$X,$U:$U,F20) -> 0 | L20: =sumifs($X:$X,$S:$S,$L$18,$U:$U,J20) -> 0 | M20: =K20-L20 -> 0 | O20: =sumifs($X:$X,$S:$S,$O$18,$U:$U,J20) -> 0 | P20: =N20-O20 -> 0
H21: =sumifs($X:$X,$U:$U,F21) -> 0 | L21: =sumifs($X:$X,$S:$S,$L$18,$U:$U,J21) -> 0 | M21: =K21-L21 -> 0 | O21: =sumifs($X:$X,$S:$S,$O$18,$U:$U,J21) -> 0 | P21: =N21-O21 -> 0
H22: =sumifs($X:$X,$U:$U,F22) -> 0 | L22: =sumifs($X:$X,$S:$S,$L$18,$U:$U,J22) -> 0 | M22: =K22-L22 -> 0 | O22: =sumifs($X:$X,$S:$S,$O$18,$U:$U,J22) -> 0 | P22: =N22-O22 -> 0
H23: =sumifs($X:$X,$U:$U,F23) -> 0 | L23: =sumifs($X:$X,$S:$S,$L$18,$U:$U,J23) -> 0 | M23: =K23-L23 -> 0 | O23: =sumifs($X:$X,$S:$S,$O$18,$U:$U,J23) -> 0 | P23: =N23-O23 -> 0
H24: =sumifs($X:$X,$U:$U,F24) -> 0 | L24: =sumifs($X:$X,$S:$S,$L$18,$U:$U,J24) -> 0 | M24: =K24-L24 -> 0 | O24: =sumifs($X:$X,$S:$S,$O$18,$U:$U,J24) -> 0 | P24: =N24-O24 -> 0
H25: =sumifs($X:$X,$U:$U,F25) -> 0 | L25: =sumifs($X:$X,$S:$S,$L$18,$U:$U,J25) -> 0 | M25: =K25-L25 -> 0 | O25: =sumifs($X:$X,$S:$S,$O$18,$U:$U,J25) -> 0 | P25: =N25-O25 -> 0
H26: =sumifs($X:$X,$U:$U,F26) -> 0 | L26: =sumifs($X:$X,$S:$S,$L$18,$U:$U,J26) -> 0 | M26: =K26-L26 -> 0 | O26: =sumifs($X:$X,$S:$S,$O$18,$U:$U,J26) -> 0 | P26: =N26-O26 -> 0
H27: =sumifs($X:$X,$U:$U,F27) -> 0 | J27: ALL | K27: =SUM(K20:K26) -> 0 | L27: =SUM(L20:L26) -> 0 | M27: =K27-L27 -> 0 | N27: =SUM(N20:N26) -> 0 | O27: =SUM(O20:O26) -> 0 | P27: =N27-O27 -> 0
H28: =sumifs($X:$X,$U:$U,F28) -> 0
H29: =sumifs($X:$X,$U:$U,F29) -> 0 | J29: 項目 | L29: 3week | O29: 4week
H30: =sumifs($X:$X,$U:$U,F30) -> 0 | K30: 予算 | L30: 金額 | M30: 差分 | N30: 予算 | O30: 金額 | P30: 差分
B31: 合計 | D31: =SUM(D19:D30) -> 0 | F31: 合計 | G31: =SUM(G19:G30) -> 0 | H31: =SUM(H19:H30) -> 0 | L31: =sumifs($X:$X,$S:$S,$L$29,$U:$U,J31) -> 0 | M31: =K31-L31 -> 0 | O31: =sumifs($X:$X,$S:$S,$O$29,$U:$U,J31) -> 0 | P31: =N31-O31 -> 0
L32: =sumifs($X:$X,$S:$S,$L$29,$U:$U,J32) -> 0 | M32: =K32-L32 -> 0 | O32: =sumifs($X:$X,$S:$S,$O$29,$U:$U,J32) -> 0 | P32: =N32-O32 -> 0
B33: 特別費 | F33: 今月の収支 | H33: 金額 | L33: =sumifs($X:$X,$S:$S,$L$29,$U:$U,J33) -> 0 | M33: =K33-L33 -> 0 | O33: =sumifs($X:$X,$S:$S,$O$29,$U:$U,J33) -> 0 | P33: =N33-O33 -> 0
B34: 費目 | C34: 支払方法 | D34: 金額 | F34: 収入（a） | H34: =D14 -> 0 | L34: =sumifs($X:$X,$S:$S,$L$29,$U:$U,J34) -> 0 | M34: =K34-L34 -> 0 | O34: =sumifs($X:$X,$S:$S,$O$29,$U:$U,J34) -> 0 | P34: =N34-O34 -> 0
F35: 先取り貯金・投資（b） | H35: =H14 -> 0 | L35: =sumifs($X:$X,$S:$S,$L$29,$U:$U,J35) -> 0 | M35: =K35-L35 -> 0 | O35: =sumifs($X:$X,$S:$S,$O$29,$U:$U,J35) -> 0 | P35: =N35-O35 -> 0
F36: 支出（c） | H36: =D31+H31 -> 0 | L36: =sumifs($X:$X,$S:$S,$L$29,$U:$U,J36) -> 0 | M36: =K36-L36 -> 0 | O36: =sumifs($X:$X,$S:$S,$O$29,$U:$U,J36) -> 0 | P36: =N36-O36 -> 0
F37: 余り貯金（d）※a-b-c | H37: =H34-H35-H36 -> 0 | L37: =sumifs($X:$X,$S:$S,$L$29,$U:$U,J37) -> 0 | M37: =K37-L37 -> 0 | O37: =sumifs($X:$X,$S:$S,$O$29,$U:$U,J37) -> 0 | P37: =N37-O37 -> 0
F38: 貯蓄合計（e）※b+d | H38: =H35+H37 -> 0 | J38: ALL | K38: =SUM(K31:K37) -> 0 | L38: =SUM(L31:L37) -> 0 | M38: =K38-L38 -> 0 | N38: =SUM(N31:N37) -> 0 | O38: =SUM(O31:O37) -> 0 | P38: =N38-O38 -> 0
F40: 支出率（c/a)×100 | G40: 貯蓄率 （e/a)×100 | J40: 項目 | L40: 5week | O40: ALL
F41: =H36/H34 -> #DIV/0! | G41: =H38/H34 -> #DIV/0! | K41: 予算 | L41: 金額 | M41: 差分 | N41: 予算 | O41: 金額 | P41: 差分
B42: 合計 | D42: =SUM(D35:D41) -> 0 | L42: =sumifs($X:$X,$S:$S,$L$40,$U:$U,J42) -> 0 | M42: =K42-L42 -> 0 | N42: =K20+N20+K31+N31+K42 -> 0 | O42: =L20+O20+L31+O31+L42 -> 0 | P42: =N42-O42 -> 0
D43: ※収支の計算外 | F43: ※目標：80%以下 | H43: ※目標：20%以上 | L43: =sumifs($X:$X,$S:$S,$L$40,$U:$U,J43) -> 0 | M43: =K43-L43 -> 0 | N43: =K21+N21+K32+N32+K43 -> 0 | O43: =L21+O21+L32+O32+L43 -> 0 | P43: =N43-O43 -> 0
...

Sheet 5月
B1: 5 | D1: ← 年・月を変更するとカレンダーが自動更新されます | J1: ※グレーのセルは自動反映します（入力不要）
B2: 2025 | J2: =DATE(B2,B1,1) -> 45778 | R2: 変動費 明細
B4: 収入 | F4: 先取り貯金・投資 | J4: 月 | K4: 火 | L4: 水 | M4: 木 | N4: 金 | O4: 土 | P4: 日 | R4: 日付 | S4: 週 | T4: 支払方法 | U4: 費目 | V4: 詳細 | X4: 金額 | Y4: 満足度
B5: 費目 | C5: 入金口座 | D5: 金額 | F5: 費目 | G5: 支払方法 | H5: 金額 | J5: =$J$2-weekday($J$2)+2 -> 45775 | K5: =J5+1 -> 45776 | L5: =K5+1 -> 45777 | M5: =L5+1 -> 45778 | N5: =M5+1 -> 45779 | O5: =N5+1 -> 45780 | P5: =O5+1 -> 45781 | R5: 45778
J6: =sumifs($X:$X,$R:$R,J5) -> 0 | K6: =sumifs($X:$X,$R:$R,K5) -> 0 | L6: =sumifs($X:$X,$R:$R,L5) -> 0 | M6: =sumifs($X:$X,$R:$R,M5) -> 0 | N6: =sumifs($X:$X,$R:$R,N5) -> 0 | O6: =sumifs($X:$X,$R:$R,O5) -> 0 | P6: =sumifs($X:$X,$R:$R,P5) -> 0
J7: =J5+7 -> 45782 | K7: =K5+7 -> 45783 | L7: =L5+7 -> 45784 | M7: =M5+7 -> 45785 | N7: =N5+7 -> 45786 | O7: =O5+7 -> 45787 | P7: =P5+7 -> 45788
J8: =sumifs($X:$X,$R:$R,J7) -> 0 | K8: =sumifs($X:$X,$R:$R,K7) -> 0 | L8: =sumifs($X:$X,$R:$R,L7) -> 0 | M8: =sumifs($X:$X,$R:$R,M7) -> 0 | N8: =sumifs($X:$X,$R:$R,N7) -> 0 | O8: =sumifs($X:$X,$R:$R,O7) -> 0 | P8: =sumifs($X:$X,$R:$R,P7) -> 0
J9: =J7+7 -> 45789 | K9: =K7+7 -> 45790 | L9: =L7+7 -> 45791 | M9: =M7+7 -> 45792 | N9: =N7+7 -> 45793 | O9: =O7+7 -> 45794 | P9: =P7+7 -> 45795
J10: =sumifs($X:$X,$R:$R,J9) -> 0 | K10: =sumifs($X:$X,$R:$R,K9) -> 0 | L10: =sumifs($X:$X,$R:$R,L9) -> 0 | M10: =sumifs($X:$X,$R:$R,M9) -> 0 | N10: =sumifs($X:$X,$R:$R,N9) -> 0 | O10: =sumifs($X:$X,$R:$R,O9) -> 0 | P10: =sumifs($X:$X,$R:$R,P9) -> 0
J11: =J9+7 -> 45796 | K11: =K9+7 -> 45797 | L11: =L9+7 -> 45798 | M11: =M9+7 -> 45799 | N11: =N9+7 -> 45800 | O11: =O9+7 -> 45801 | P11: =P9+7 -> 45802
J12: =sumifs($X:$X,$R:$R,J11) -> 0 | K12: =sumifs($X:$X,$R:$R,K11) -> 0 | L12: =sumifs($X:$X,$R:$R,L11) -> 0 | M12: =sumifs($X:$X,$R:$R,M11) -> 0 | N12: =sumifs($X:$X,$R:$R,N11) -> 0 | O12: =sumifs($X:$X,$R:$R,O11) -> 0 | P12: =sumifs($X:$X,$R:$R,P11) -> 0
J13: =J11+7 -> 45803 | K13: =K11+7 -> 45804 | L13: =L11+7 -> 45805 | M13: =M11+7 -> 45806 | N13: =N11+7 -> 45807 | O13: =O11+7 -> 45808 | P13: =P11+7 -> 45809
B14: 合計 | D14: =SUM(D6:D13) -> 0 | F14: 合計 | H14: =SUM(H6:H13) -> 0 | J14: =sumifs($X:$X,$R:$R,J13) -> 0 | K14: =sumifs($X:$X,$R:$R,K13) -> 0 | L14: =sumifs($X:$X,$R:$R,L13) -> 0 | M14: =sumifs($X:$X,$R:$R,M13) -> 0 | N14: =sumifs($X:$X,$R:$R,N13) -> 0 | O14: =sumifs($X:$X,$R:$R,O13) -> 0 | P14: =sumifs($X:$X,$R:$R,P13) -> 0
B16: 支出 | F16: 支出 | J16: 週予算 管理
B17: 固定費 | F17: 変動費
B18: 費目 | C18: 支払方法 | D18: 金額 | F18: 費目 | G18: 予算 | H18: 金額 | J18: 項目 | L18: 1week | O18: 2week
H19: =sumifs($X:$X,$U:$U,F19) -> 0 | K19: 予算 | L19: 金額 | M19: 差分 | N19: 予算 | O19: 金額 | P19: 差分
H20: =sumifs($X:$X,$U:$U,F20) -> 0 | L20: =sumifs($X:$X,$S:$S,$L$18,$U:$U,J20) -> 0 | M20: =K20-L20 -> 0 | O20: =sumifs($X:$X,$S:$S,$O$18,$U:$U,J20) -> 0 | P20: =N20-O20 -> 0
H21: =sumifs($X:$X,$U:$U,F21) -> 0 | L21: =sumifs($X:$X,$S:$S,$L$18,$U:$U,J21) -> 0 | M21: =K21-L21 -> 0 | O21: =sumifs($X:$X,$S:$S,$O$18,$U:$U,J21) -> 0 | P21: =N21-O21 -> 0
H22: =sumifs($X:$X,$U:$U,F22) -> 0 | L22: =sumifs($X:$X,$S:$S,$L$18,$U:$U,J22) -> 0 | M22: =K22-L22 -> 0 | O22: =sumifs($X:$X,$S:$S,$O$18,$U:$U,J22) -> 0 | P22: =N22-O22 -> 0
H23: =sumifs($X:$X,$U:$U,F23) -> 0 | L23: =sumifs($X:$X,$S:$S,$L$18,$U:$U,J23) -> 0 | M23: =K23-L23 -> 0 | O23: =sumifs($X:$X,$S:$S,$O$18,$U:$U,J23) -> 0 | P23: =N23-O23 -> 0
H24: =sumifs($X:$X,$U:$U,F24) -> 0 | L24: =sumifs($X:$X,$S:$S,$L$18,$U:$U,J24) -> 0 | M24: =K24-L24 -> 0 | O24: =sumifs($X:$X,$S:$S,$O$18,$U:$U,J24) -> 0 | P24: =N24-O24 -> 0
H25: =sumifs($X:$X,$U:$U,F25) -> 0 | L25: =sumifs($X:$X,$S:$S,$L$18,$U:$U,J25) -> 0 | M25: =K25-L25 -> 0 | O25: =sumifs($X:$X,$S:$S,$O$18,$U:$U,J25) -> 0 | P25: =N25-O25 -> 0
H26: =sumifs($X:$X,$U:$U,F26) -> 0 | L26: =sumifs($X:$X,$S:$S,$L$18,$U:$U,J26) -> 0 | M26: =K26-L26 -> 0 | O26: =sumifs($X:$X,$S:$S,$O$18,$U:$U,J26) -> 0 | P26: =N26-O26 -> 0
H27: =sumifs($X:$X,$U:$U,F27) -> 0 | J27: ALL | K27: =SUM(K20:K26) -> 0 | L27: =SUM(L20:L26) -> 0 | M27: =K27-L27 -> 0 | N27: =SUM(N20:N26) -> 0 | O27: =SUM(O20:O26) -> 0 | P27: =N27-O27 -> 0
H28: =sumifs($X:$X,$U:$U,F28) -> 0
H29: =sumifs($X:$X,$U:$U,F29) -> 0 | J29: 項目 | L29: 3week | O29: 4week
H30: =sumifs($X:$X,$U:$U,F30) -> 0 | K30: 予算 | L30: 金額 | M30: 差分 | N30: 予算 | O30: 金額 | P30: 差分
B31: 合計 | D31: =SUM(D19:D30) -> 0 | F31: 合計 | G31: =SUM(G19:G30) -> 0 | H31: =SUM(H19:H30) -> 0 | L31: =sumifs($X:$X,$S:$S,$L$29,$U:$U,J31) -> 0 | M31: =K31-L31 -> 0 | O31: =sumifs($X:$X,$S:$S,$O$29,$U:$U,J31) -> 0 | P31: =N31-O31 -> 0
L32: =sumifs($X:$X,$S:$S,$L$29,$U:$U,J32) -> 0 | M32: =K32-L32 -> 0 | O32: =sumifs($X:$X,$S:$S,$O$29,$U:$U,J32) -> 0 | P32: =N32-O32 -> 0
B33: 特別費 | F33: 今月の収支 | H33: 金額 | L33: =sumifs($X:$X,$S:$S,$L$29,$U:$U,J33) -> 0 | M33: =K33-L33 -> 0 | O33: =sumifs($X:$X,$S:$S,$O$29,$U:$U,J33) -> 0 | P33: =N33-O33 -> 0
B34: 費目 | C34: 支払方法 | D34: 金額 | F34: 収入（a） | H34: =D14 -> 0 | L34: =sumifs($X:$X,$S:$S,$L$29,$U:$U,J34) -> 0 | M34: =K34-L34 -> 0 | O34: =sumifs($X:$X,$S:$S,$O$29,$U:$U,J34) -> 0 | P34: =N34-O34 -> 0
F35: 先取り貯金・投資（b） | H35: =H14 -> 0 | L35: =sumifs($X:$X,$S:$S,$L$29,$U:$U,J35) -> 0 | M35: =K35-L35 -> 0 | O35: =sumifs($X:$X,$S:$S,$O$29,$U:$U,J35) -> 0 | P35: =N35-O35 -> 0
F36: 支出（c） | H36: =D31+H31 -> 0 | L36: =sumifs($X:$X,$S:$S,$L$29,$U:$U,J36) -> 0 | M36: =K36-L36 -> 0 | O36: =sumifs($X:$X,$S:$S,$O$29,$U:$U,J36) -> 0 | P36: =N36-O36 -> 0
F37: 余り貯金（d）※a-b-c | H37: =H34-H35-H36 -> 0 | L37: =sumifs($X:$X,$S:$S,$L$29,$U:$U,J37) -> 0 | M37: =K37-L37 -> 0 | O37: =sumifs($X:$X,$S:$S,$O$29,$U:$U,J37) -> 0 | P37: =N37-O37 -> 0
F38: 貯蓄合計（e）※b+d | H38: =H35+H37 -> 0 | J38: ALL | K38: =SUM(K31:K37) -> 0 | L38: =SUM(L31:L37) -> 0 | M38: =K38-L38 -> 0 | N38: =SUM(N31:N37) -> 0 | O38: =SUM(O31:O37) -> 0 | P38: =N38-O38 -> 0
F40: 支出率（c/a)×100 | G40: 貯蓄率 （e/a)×100 | J40: 項目 | L40: 5week | O40: ALL
F41: =H36/H34 -> #DIV/0! | G41: =H38/H34 -> #DIV/0! | K41: 予算 | L41: 金額 | M41: 差分 | N41: 予算 | O41: 金額 | P41: 差分
B42: 合計 | D42: =SUM(D35:D41) -> 0 | L42: =sumifs($X:$X,$S:$S,$L$40,$U:$U,J42) -> 0 | M42: =K42-L42 -> 0 | N42: =K20+N20+K31+N31+K42 -> 0 | O42: =L20+O20+L31+O31+L42 -> 0 | P42: =N42-O42 -> 0
D43: ※収支の計算外 | F43: ※目標：80%以下 | H43: ※目標：20%以上 | L43: =sumifs($X:$X,$S:$S,$L$40,$U:$U,J43) -> 0 | M43: =K43-L43 -> 0 | N43: =K21+N21+K32+N32+K43 -> 0 | O43: =L21+O21+L32+O32+L43 -> 0 | P43: =N43-O43 -> 0
...

Sheet 6月
B1: 6 | D1: ← 年・月を変更するとカレンダーが自動更新されます | J1: ※グレーのセルは自動反映します（入力不要）
B2: 2025 | J2: =DATE(B2,B1,1) -> 45809 | R2: 変動費 明細
B4: 収入 | F4: 先取り貯金・投資 | J4: 月 | K4: 火 | L4: 水 | M4: 木 | N4: 金 | O4: 土 | P4: 日 | R4: 日付 | S4: 週 | T4: 支払方法 | U4: 費目 | V4: 詳細 | X4: 金額 | Y4: 満足度
B5: 費目 | C5: 入金口座 | D5: 金額 | F5: 費目 | G5: 支払方法 | H5: 金額 | J5: =$J$2-weekday($J$2)+2 -> 45810 | K5: =J5+1 -> 45811 | L5: =K5+1 -> 45812 | M5: =L5+1 -> 45813 | N5: =M5+1 -> 45814 | O5: =N5+1 -> 45815 | P5: =O5+1 -> 45816 | R5: 45810
J6: =sumifs($X:$X,$R:$R,J5) -> 0 | K6: =sumifs($X:$X,$R:$R,K5) -> 0 | L6: =sumifs($X:$X,$R:$R,L5) -> 0 | M6: =sumifs($X:$X,$R:$R,M5) -> 0 | N6: =sumifs($X:$X,$R:$R,N5) -> 0 | O6: =sumifs($X:$X,$R:$R,O5) -> 0 | P6: =sumifs($X:$X,$R:$R,P5) -> 0
J7: =J5+7 -> 45817 | K7: =K5+7 -> 45818 | L7: =L5+7 -> 45819 | M7: =M5+7 -> 45820 | N7: =N5+7 -> 45821 | O7: =O5+7 -> 45822 | P7: =P5+7 -> 45823
J8: =sumifs($X:$X,$R:$R,J7) -> 0 | K8: =sumifs($X:$X,$R:$R,K7) -> 0 | L8: =sumifs($X:$X,$R:$R,L7) -> 0 | M8: =sumifs($X:$X,$R:$R,M7) -> 0 | N8: =sumifs($X:$X,$R:$R,N7) -> 0 | O8: =sumifs($X:$X,$R:$R,O7) -> 0 | P8: =sumifs($X:$X,$R:$R,P7) -> 0
J9: =J7+7 -> 45824 | K9: =K7+7 -> 45825 | L9: =L7+7 -> 45826 | M9: =M7+7 -> 45827 | N9: =N7+7 -> 45828 | O9: =O7+7 -> 45829 | P9: =P7+7 -> 45830
J10: =sumifs($X:$X,$R:$R,J9) -> 0 | K10: =sumifs($X:$X,$R:$R,K9) -> 0 | L10: =sumifs($X:$X,$R:$R,L9) -> 0 | M10: =sumifs($X:$X,$R:$R,M9) -> 0 | N10: =sumifs($X:$X,$R:$R,N9) -> 0 | O10: =sumifs($X:$X,$R:$R,O9) -> 0 | P10: =sumifs($X:$X,$R:$R,P9) -> 0
J11: =J9+7 -> 45831 | K11: =K9+7 -> 45832 | L11: =L9+7 -> 45833 | M11: =M9+7 -> 45834 | N11: =N9+7 -> 45835 | O11: =O9+7 -> 45836 | P11: =P9+7 -> 45837
J12: =sumifs($X:$X,$R:$R,J11) -> 0 | K12: =sumifs($X:$X,$R:$R,K11) -> 0 | L12: =sumifs($X:$X,$R:$R,L11) -> 0 | M12: =sumifs($X:$X,$R:$R,M11) -> 0 | N12: =sumifs($X:$X,$R:$R,N11) -> 0 | O12: =sumifs($X:$X,$R:$R,O11) -> 0 | P12: =sumifs($X:$X,$R:$R,P11) -> 0
J13: =J11+7 -> 45838 | K13: =K11+7 -> 45839 | L13: =L11+7 -> 45840 | M13: =M11+7 -> 45841 | N13: =N11+7 -> 45842 | O13: =O11+7 -> 45843 | P13: =P11+7 -> 45844
B14: 合計 | D14: =SUM(D6:D13) -> 0 | F14: 合計 | H14: =SUM(H6:H13) -> 0 | J14: =sumifs($X:$X,$R:$R,J13) -> 0 | K14: =sumifs($X:$X,$R:$R,K13) -> 0 | L14: =sumifs($X:$X,$R:$R,L13) -> 0 | M14: =sumifs($X:$X,$R:$R,M13) -> 0 | N14: =sumifs($X:$X,$R:$R,N13) -> 0 | O14: =sumifs($X:$X,$R:$R,O13) -> 0 | P14: =sumifs($X:$X,$R:$R,P13) -> 0
B16: 支出 | F16: 支出 | J16: 週予算 管理
B17: 固定費 | F17: 変動費
B18: 費目 | C18: 支払方法 | D18: 金額 | F18: 費目 | G18: 予算 | H18: 金額 | J18: 項目 | L18: 1week | O18: 2week
H19: =sumifs($X:$X,$U:$U,F19) -> 0 | K19: 予算 | L19: 金額 | M19: 差分 | N19: 予算 | O19: 金額 | P19: 差分
H20: =sumifs($X:$X,$U:$U,F20) -> 0 | L20: =sumifs($X:$X,$S:$S,$L$18,$U:$U,J20) -> 0 | M20: =K20-L20 -> 0 | O20: =sumifs($X:$X,$S:$S,$O$18,$U:$U,J20) -> 0 | P20: =N20-O20 -> 0
H21: =sumifs($X:$X,$U:$U,F21) -> 0 | L21: =sumifs($X:$X,$S:$S,$L$18,$U:$U,J21) -> 0 | M21: =K21-L21 -> 0 | O21: =sumifs($X:$X,$S:$S,$O$18,$U:$U,J21) -> 0 | P21: =N21-O21 -> 0
H22: =sumifs($X:$X,$U:$U,F22) -> 0 | L22: =sumifs($X:$X,$S:$S,$L$18,$U:$U,J22) -> 0 | M22: =K22-L22 -> 0 | O22: =sumifs($X:$X,$S:$S,$O$18,$U:$U,J22) -> 0 | P22: =N22-O22 -> 0
H23: =sumifs($X:$X,$U:$U,F23) -> 0 | L23: =sumifs($X:$X,$S:$S,$L$18,$U:$U,J23) -> 0 | M23: =K23-L23 -> 0 | O23: =sumifs($X:$X,$S:$S,$O$18,$U:$U,J23) -> 0 | P23: =N23-O23 -> 0
H24: =sumifs($X:$X,$U:$U,F24) -> 0 | L24: =sumifs($X:$X,$S:$S,$L$18,$U:$U,J24) -> 0 | M24: =K24-L24 -> 0 | O24: =sumifs($X:$X,$S:$S,$O$18,$U:$U,J24) -> 0 | P24: =N24-O24 -> 0
H25: =sumifs($X:$X,$U:$U,F25) -> 0 | L25: =sumifs($X:$X,$S:$S,$L$18,$U:$U,J25) -> 0 | M25: =K25-L25 -> 0 | O25: =sumifs($X:$X,$S:$S,$O$18,$U:$U,J25) -> 0 | P25: =N25-O25 -> 0
H26: =sumifs($X:$X,$U:$U,F26) -> 0 | L26: =sumifs($X:$X,$S:$S,$L$18,$U:$U,J26) -> 0 | M26: =K26-L26 -> 0 | O26: =sumifs($X:$X,$S:$S,$O$18,$U:$U,J26) -> 0 | P26: =N26-O26 -> 0
H27: =sumifs($X:$X,$U:$U,F27) -> 0 | J27: ALL | K27: =SUM(K20:K26) -> 0 | L27: =SUM(L20:L26) -> 0 | M27: =K27-L27 -> 0 | N27: =SUM(N20:N26) -> 0 | O27: =SUM(O20:O26) -> 0 | P27: =N27-O27 -> 0
H28: =sumifs($X:$X,$U:$U,F28) -> 0
H29: =sumifs($X:$X,$U:$U,F29) -> 0 | J29: 項目 | L29: 3week | O29: 4week
H30: =sumifs($X:$X,$U:$U,F30) -> 0 | K30: 予算 | L30: 金額 | M30: 差分 | N30: 予算 | O30: 金額 | P30: 差分
B31: 合計 | D31: =SUM(D19:D30) -> 0 | F31: 合計 | G31: =SUM(G19:G30) -> 0 | H31: =SUM(H19:H30) -> 0 | L31: =sumifs($X:$X,$S:$S,$L$29,$U:$U,J31) -> 0 | M31: =K31-L31 -> 0 | O31: =sumifs($X:$X,$S:$S,$O$29,$U:$U,J31) -> 0 | P31: =N31-O31 -> 0
L32: =sumifs($X:$X,$S:$S,$L$29,$U:$U,J32) -> 0 | M32: =K32-L32 -> 0 | O32: =sumifs($X:$X,$S:$S,$O$29,$U:$U,J32) -> 0 | P32: =N32-O32 -> 0
B33: 特別費 | F33: 今月の収支 | H33: 金額 | L33: =sumifs($X:$X,$S:$S,$L$29,$U:$U,J33) -> 0 | M33: =K33-L33 -> 0 | O33: =sumifs($X:$X,$S:$S,$O$29,$U:$U,J33) -> 0 | P33: =N33-O33 -> 0
B34: 費目 | C34: 支払方法 | D34: 金額 | F34: 収入（a） | H34: =D14 -> 0 | L34: =sumifs($X:$X,$S:$S,$L$29,$U:$U,J34) -> 0 | M34: =K34-L34 -> 0 | O34: =sumifs($X:$X,$S:$S,$O$29,$U:$U,J34) -> 0 | P34: =N34-O34 -> 0
F35: 先取り貯金・投資（b） | H35: =H14 -> 0 | L35: =sumifs($X:$X,$S:$S,$L$29,$U:$U,J35) -> 0 | M35: =K35-L35 -> 0 | O35: =sumifs($X:$X,$S:$S,$O$29,$U:$U,J35) -> 0 | P35: =N35-O35 -> 0
F36: 支出（c） | H36: =D31+H31 -> 0 | L36: =sumifs($X:$X,$S:$S,$L$29,$U:$U,J36) -> 0 | M36: =K36-L36 -> 0 | O36: =sumifs($X:$X,$S:$S,$O$29,$U:$U,J36) -> 0 | P36: =N36-O36 -> 0
F37: 余り貯金（d）※a-b-c | H37: =H34-H35-H36 -> 0 | L37: =sumifs($X:$X,$S:$S,$L$29,$U:$U,J37) -> 0 | M37: =K37-L37 -> 0 | O37: =sumifs($X:$X,$S:$S,$O$29,$U:$U,J37) -> 0 | P37: =N37-O37 -> 0
F38: 貯蓄合計（e）※b+d | H38: =H35+H37 -> 0 | J38: ALL | K38: =SUM(K31:K37) -> 0 | L38: =SUM(L31:L37) -> 0 | M38: =K38-L38 -> 0 | N38: =SUM(N31:N37) -> 0 | O38: =SUM(O31:O37) -> 0 | P38: =N38-O38 -> 0
F40: 支出率（c/a)×100 | G40: 貯蓄率 （e/a)×100 | J40: 項目 | L40: 5week | O40: ALL
F41: =H36/H34 -> #DIV/0! | G41: =H38/H34 -> #DIV/0! | K41: 予算 | L41: 金額 | M41: 差分 | N41: 予算 | O41: 金額 | P41: 差分
B42: 合計 | D42: =SUM(D35:D41) -> 0 | L42: =sumifs($X:$X,$S:$S,$L$40,$U:$U,J42) -> 0 | M42: =K42-L42 -> 0 | N42: =K20+N20+K31+N31+K42 -> 0 | O42: =L20+O20+L31+O31+L42 -> 0 | P42: =N42-O42 -> 0
D43: ※収支の計算外 | F43: ※目標：80%以下 | H43: ※目標：20%以上 | L43: =sumifs($X:$X,$S:$S,$L$40,$U:$U,J43) -> 0 | M43: =K43-L43 -> 0 | N43: =K21+N21+K32+N32+K43 -> 0 | O43: =L21+O21+L32+O32+L43 -> 0 | P43: =N43-O43 -> 0
...

Sheet 7月
B1: 7 | D1: ← 年・月を変更するとカレンダーが自動更新されます | J1: ※グレーのセルは自動反映します（入力不要）
B2: 2025 | J2: =DATE(B2,B1,1) -> 45839 | R2: 変動費 明細
B4: 収入 | F4: 先取り貯金・投資 | J4: 月 | K4: 火 | L4: 水 | M4: 木 | N4: 金 | O4: 土 | P4: 日 | R4: 日付 | S4: 週 | T4: 支払方法 | U4: 費目 | V4: 詳細 | X4: 金額 | Y4: 満足度
B5: 費目 | C5: 入金口座 | D5: 金額 | F5: 費目 | G5: 支払方法 | H5: 金額 | J5: =$J$2-weekday($J$2)+2 -> 45838 | K5: =J5+1 -> 45839 | L5: =K5+1 -> 45840 | M5: =L5+1 -> 45841 | N5: =M5+1 -> 45842 | O5: =N5+1 -> 45843 | P5: =O5+1 -> 45844 | R5: 45839
J6: =sumifs($X:$X,$R:$R,J5) -> 0 | K6: =sumifs($X:$X,$R:$R,K5) -> 0 | L6: =sumifs($X:$X,$R:$R,L5) -> 0 | M6: =sumifs($X:$X,$R:$R,M5) -> 0 | N6: =sumifs($X:$X,$R:$R,N5) -> 0 | O6: =sumifs($X:$X,$R:$R,O5) -> 0 | P6: =sumifs($X:$X,$R:$R,P5) -> 0
J7: =J5+7 -> 45845 | K7: =K5+7 -> 45846 | L7: =L5+7 -> 45847 | M7: =M5+7 -> 45848 | N7: =N5+7 -> 45849 | O7: =O5+7 -> 45850 | P7: =P5+7 -> 45851
J8: =sumifs($X:$X,$R:$R,J7) -> 0 | K8: =sumifs($X:$X,$R:$R,K7) -> 0 | L8: =sumifs($X:$X,$R:$R,L7) -> 0 | M8: =sumifs($X:$X,$R:$R,M7) -> 0 | N8: =sumifs($X:$X,$R:$R,N7) -> 0 | O8: =sumifs($X:$X,$R:$R,O7) -> 0 | P8: =sumifs($X:$X,$R:$R,P7) -> 0
J9: =J7+7 -> 45852 | K9: =K7+7 -> 45853 | L9: =L7+7 -> 45854 | M9: =M7+7 -> 45855 | N9: =N7+7 -> 45856 | O9: =O7+7 -> 45857 | P9: =P7+7 -> 45858
J10: =sumifs($X:$X,$R:$R,J9) -> 0 | K10: =sumifs($X:$X,$R:$R,K9) -> 0 | L10: =sumifs($X:$X,$R:$R,L9) -> 0 | M10: =sumifs($X:$X,$R:$R,M9) -> 0 | N10: =sumifs($X:$X,$R:$R,N9) -> 0 | O10: =sumifs($X:$X,$R:$R,O9) -> 0 | P10: =sumifs($X:$X,$R:$R,P9) -> 0
J11: =J9+7 -> 45859 | K11: =K9+7 -> 45860 | L11: =L9+7 -> 45861 | M11: =M9+7 -> 45862 | N11: =N9+7 -> 45863 | O11: =O9+7 -> 45864 | P11: =P9+7 -> 45865
J12: =sumifs($X:$X,$R:$R,J11) -> 0 | K12: =sumifs($X:$X,$R:$R,K11) -> 0 | L12: =sumifs($X:$X,$R:$R,L11) -> 0 | M12: =sumifs($X:$X,$R:$R,M11) -> 0 | N12: =sumifs($X:$X,$R:$R,N11) -> 0 | O12: =sumifs($X:$X,$R:$R,O11) -> 0 | P12: =sumifs($X:$X,$R:$R,P11) -> 0
J13: =J11+7 -> 45866 | K13: =K11+7 -> 45867 | L13: =L11+7 -> 45868 | M13: =M11+7 -> 45869 | N13: =N11+7 -> 45870 | O13: =O11+7 -> 45871 | P13: =P11+7 -> 45872
B14: 合計 | D14: =SUM(D6:D13) -> 0 | F14: 合計 | H14: =SUM(H6:H13) -> 0 | J14: =sumifs($X:$X,$R:$R,J13) -> 0 | K14: =sumifs($X:$X,$R:$R,K13) -> 0 | L14: =sumifs($X:$X,$R:$R,L13) -> 0 | M14: =sumifs($X:$X,$R:$R,M13) -> 0 | N14: =sumifs($X:$X,$R:$R,N13) -> 0 | O14: =sumifs($X:$X,$R:$R,O13) -> 0 | P14: =sumifs($X:$X,$R:$R,P13) -> 0
B16: 支出 | F16: 支出 | J16: 週予算 管理
B17: 固定費 | F17: 変動費
B18: 費目 | C18: 支払方法 | D18: 金額 | F18: 費目 | G18: 予算 | H18: 金額 | J18: 項目 | L18: 1week | O18: 2week
H19: =sumifs($X:$X,$U:$U,F19) -> 0 | K19: 予算 | L19: 金額 | M19: 差分 | N19: 予算 | O19: 金額 | P19: 差分
H20: =sumifs($X:$X,$U:$U,F20) -> 0 | L20: =sumifs($X:$X,$S:$S,$L$18,$U:$U,J20) -> 0 | M20: =K20-L20 -> 0 | O20: =sumifs($X:$X,$S:$S,$O$18,$U:$U,J20) -> 0 | P20: =N20-O20 -> 0
H21: =sumifs($X:$X,$U:$U,F21) -> 0 | L21: =sumifs($X:$X,$S:$S,$L$18,$U:$U,J21) -> 0 | M21: =K21-L21 -> 0 | O21: =sumifs($X:$X,$S:$S,$O$18,$U:$U,J21) -> 0 | P21: =N21-O21 -> 0
H22: =sumifs($X:$X,$U:$U,F22) -> 0 | L22: =sumifs($X:$X,$S:$S,$L$18,$U:$U,J22) -> 0 | M22: =K22-L22 -> 0 | O22: =sumifs($X:$X,$S:$S,$O$18,$U:$U,J22) -> 0 | P22: =N22-O22 -> 0
H23: =sumifs($X:$X,$U:$U,F23) -> 0 | L23: =sumifs($X:$X,$S:$S,$L$18,$U:$U,J23) -> 0 | M23: =K23-L23 -> 0 | O23: =sumifs($X:$X,$S:$S,$O$18,$U:$U,J23) -> 0 | P23: =N23-O23 -> 0
H24: =sumifs($X:$X,$U:$U,F24) -> 0 | L24: =sumifs($X:$X,$S:$S,$L$18,$U:$U,J24) -> 0 | M24: =K24-L24 -> 0 | O24: =sumifs($X:$X,$S:$S,$O$18,$U:$U,J24) -> 0 | P24: =N24-O24 -> 0
H25: =sumifs($X:$X,$U:$U,F25) -> 0 | L25: =sumifs($X:$X,$S:$S,$L$18,$U:$U,J25) -> 0 | M25: =K25-L25 -> 0 | O25: =sumifs($X:$X,$S:$S,$O$18,$U:$U,J25) -> 0 | P25: =N25-O25 -> 0
H26: =sumifs($X:$X,$U:$U,F26) -> 0 | L26: =sumifs($X:$X,$S:$S,$L$18,$U:$U,J26) -> 0 | M26: =K26-L26 -> 0 | O26: =sumifs($X:$X,$S:$S,$O$18,$U:$U,J26) -> 0 | P26: =N26-O26 -> 0
H27: =sumifs($X:$X,$U:$U,F27) -> 0 | J27: ALL | K27: =SUM(K20:K26) -> 0 | L27: =SUM(L20:L26) -> 0 | M27: =K27-L27 -> 0 | N27: =SUM(N20:N26) -> 0 | O27: =SUM(O20:O26) -> 0 | P27: =N27-O27 -> 0
H28: =sumifs($X:$X,$U:$U,F28) -> 0
H29: =sumifs($X:$X,$U:$U,F29) -> 0 | J29: 項目 | L29: 3week | O29: 4week
H30: =sumifs($X:$X,$U:$U,F30) -> 0 | K30: 予算 | L30: 金額 | M30: 差分 | N30: 予算 | O30: 金額 | P30: 差分
B31: 合計 | D31: =SUM(D19:D30) -> 0 | F31: 合計 | G31: =SUM(G19:G30) -> 0 | H31: =SUM(H19:H30) -> 0 | L31: =sumifs($X:$X,$S:$S,$L$29,$U:$U,J31) -> 0 | M31: =K31-L31 -> 0 | O31: =sumifs($X:$X,$S:$S,$O$29,$U:$U,J31) -> 0 | P31: =N31-O31 -> 0
L32: =sumifs($X:$X,$S:$S,$L$29,$U:$U,J32) -> 0 | M32: =K32-L32 -> 0 | O32: =sumifs($X:$X,$S:$S,$O$29,$U:$U,J32) -> 0 | P32: =N32-O32 -> 0
B33: 特別費 | F33: 今月の収支 | H33: 金額 | L33: =sumifs($X:$X,$S:$S,$L$29,$U:$U,J33) -> 0 | M33: =K33-L33 -> 0 | O33: =sumifs($X:$X,$S:$S,$O$29,$U:$U,J33) -> 0 | P33: =N33-O33 -> 0
B34: 費目 | C34: 支払方法 | D34: 金額 | F34: 収入（a） | H34: =D14 -> 0 | L34: =sumifs($X:$X,$S:$S,$L$29,$U:$U,J34) -> 0 | M34: =K34-L34 -> 0 | O34: =sumifs($X:$X,$S:$S,$O$29,$U:$U,J34) -> 0 | P34: =N34-O34 -> 0
F35: 先取り貯金・投資（b） | H35: =H14 -> 0 | L35: =sumifs($X:$X,$S:$S,$L$29,$U:$U,J35) -> 0 | M35: =K35-L35 -> 0 | O35: =sumifs($X:$X,$S:$S,$O$29,$U:$U,J35) -> 0 | P35: =N35-O35 -> 0
F36: 支出（c） | H36: =D31+H31 -> 0 | L36: =sumifs($X:$X,$S:$S,$L$29,$U:$U,J36) -> 0 | M36: =K36-L36 -> 0 | O36: =sumifs($X:$X,$S:$S,$O$29,$U:$U,J36) -> 0 | P36: =N36-O36 -> 0
F37: 余り貯金（d）※a-b-c | H37: =H34-H35-H36 -> 0 | L37: =sumifs($X:$X,$S:$S,$L$29,$U:$U,J37) -> 0 | M37: =K37-L37 -> 0 | O37: =sumifs($X:$X,$S:$S,$O$29,$U:$U,J37) -> 0 | P37: =N37-O37 -> 0
F38: 貯蓄合計（e）※b+d | H38: =H35+H37 -> 0 | J38: ALL | K38: =SUM(K31:K37) -> 0 | L38: =SUM(L31:L37) -> 0 | M38: =K38-L38 -> 0 | N38: =SUM(N31:N37) -> 0 | O38: =SUM(O31:O37) -> 0 | P38: =N38-O38 -> 0
F40: 支出率（c/a)×100 | G40: 貯蓄率 （e/a)×100 | J40: 項目 | L40: 5week | O40: ALL
F41: =H36/H34 -> #DIV/0! | G41: =H38/H34 -> #DIV/0! | K41: 予算 | L41: 金額 | M41: 差分 | N41: 予算 | O41: 金額 | P41: 差分
B42: 合計 | D42: =SUM(D35:D41) -> 0 | L42: =sumifs($X:$X,$S:$S,$L$40,$U:$U,J42) -> 0 | M42: =K42-L42 -> 0 | N42: =K20+N20+K31+N31+K42 -> 0 | O42: =L20+O20+L31+O31+L42 -> 0 | P42: =N42-O42 -> 0
D43: ※収支の計算外 | F43: ※目標：80%以下 | H43: ※目標：20%以上 | L43: =sumifs($X:$X,$S:$S,$L$40,$U:$U,J43) -> 0 | M43: =K43-L43 -> 0 | N43: =K21+N21+K32+N32+K43 -> 0 | O43: =L21+O21+L32+O32+L43 -> 0 | P43: =N43-O43 -> 0
...

Sheet 8月
B1: 8 | D1: ← 年・月を変更するとカレンダーが自動更新されます | J1: ※グレーのセルは自動反映します（入力不要）
B2: 2025 | J2: =DATE(B2,B1,1) -> 45870 | R2: 変動費 明細
B4: 収入 | F4: 先取り貯金・投資 | J4: 月 | K4: 火 | L4: 水 | M4: 木 | N4: 金 | O4: 土 | P4: 日 | R4: 日付 | S4: 週 | T4: 支払方法 | U4: 費目 | V4: 詳細 | X4: 金額 | Y4: 満足度
B5: 費目 | C5: 入金口座 | D5: 金額 | F5: 費目 | G5: 支払方法 | H5: 金額 | J5: =$J$2-weekday($J$2)+2 -> 45866 | K5: =J5+1 -> 45867 | L5: =K5+1 -> 45868 | M5: =L5+1 -> 45869 | N5: =M5+1 -> 45870 | O5: =N5+1 -> 45871 | P5: =O5+1 -> 45872 | R5: 45870
J6: =sumifs($X:$X,$R:$R,J5) -> 0 | K6: =sumifs($X:$X,$R:$R,K5) -> 0 | L6: =sumifs($X:$X,$R:$R,L5) -> 0 | M6: =sumifs($X:$X,$R:$R,M5) -> 0 | N6: =sumifs($X:$X,$R:$R,N5) -> 0 | O6: =sumifs($X:$X,$R:$R,O5) -> 0 | P6: =sumifs($X:$X,$R:$R,P5) -> 0
J7: =J5+7 -> 45873 | K7: =K5+7 -> 45874 | L7: =L5+7 -> 45875 | M7: =M5+7 -> 45876 | N7: =N5+7 -> 45877 | O7: =O5+7 -> 45878 | P7: =P5+7 -> 45879
J8: =sumifs($X:$X,$R:$R,J7) -> 0 | K8: =sumifs($X:$X,$R:$R,K7) -> 0 | L8: =sumifs($X:$X,$R:$R,L7) -> 0 | M8: =sumifs($X:$X,$R:$R,M7) -> 0 | N8: =sumifs($X:$X,$R:$R,N7) -> 0 | O8: =sumifs($X:$X,$R:$R,O7) -> 0 | P8: =sumifs($X:$X,$R:$R,P7) -> 0
J9: =J7+7 -> 45880 | K9: =K7+7 -> 45881 | L9: =L7+7 -> 45882 | M9: =M7+7 -> 45883 | N9: =N7+7 -> 45884 | O9: =O7+7 -> 45885 | P9: =P7+7 -> 45886
J10: =sumifs($X:$X,$R:$R,J9) -> 0 | K10: =sumifs($X:$X,$R:$R,K9) -> 0 | L10: =sumifs($X:$X,$R:$R,L9) -> 0 | M10: =sumifs($X:$X,$R:$R,M9) -> 0 | N10: =sumifs($X:$X,$R:$R,N9) -> 0 | O10: =sumifs($X:$X,$R:$R,O9) -> 0 | P10: =sumifs($X:$X,$R:$R,P9) -> 0
J11: =J9+7 -> 45887 | K11: =K9+7 -> 45888 | L11: =L9+7 -> 45889 | M11: =M9+7 -> 45890 | N11: =N9+7 -> 45891 | O11: =O9+7 -> 45892 | P11: =P9+7 -> 45893
J12: =sumifs($X:$X,$R:$R,J11) -> 0 | K12: =sumifs($X:$X,$R:$R,K11) -> 0 | L12: =sumifs($X:$X,$R:$R,L11) -> 0 | M12: =sumifs($X:$X,$R:$R,M11) -> 0 | N12: =sumifs($X:$X,$R:$R,N11) -> 0 | O12: =sumifs($X:$X,$R:$R,O11) -> 0 | P12: =sumifs($X:$X,$R:$R,P11) -> 0
J13: =J11+7 -> 45894 | K13: =K11+7 -> 45895 | L13: =L11+7 -> 45896 | M13: =M11+7 -> 45897 | N13: =N11+7 -> 45898 | O13: =O11+7 -> 45899 | P13: =P11+7 -> 45900
B14: 合計 | D14: =SUM(D6:D13) -> 0 | F14: 合計 | H14: =SUM(H6:H13) -> 0 | J14: =sumifs($X:$X,$R:$R,J13) -> 0 | K14: =sumifs($X:$X,$R:$R,K13) -> 0 | L14: =sumifs($X:$X,$R:$R,L13) -> 0 | M14: =sumifs($X:$X,$R:$R,M13) -> 0 | N14: =sumifs($X:$X,$R:$R,N13) -> 0 | O14: =sumifs($X:$X,$R:$R,O13) -> 0 | P14: =sumifs($X:$X,$R:$R,P13) -> 0
B16: 支出 | F16: 支出 | J16: 週予算 管理
B17: 固定費 | F17: 変動費
B18: 費目 | C18: 支払方法 | D18: 金額 | F18: 費目 | G18: 予算 | H18: 金額 | J18: 項目 | L18: 1week | O18: 2week
H19: =sumifs($X:$X,$U:$U,F19) -> 0 | K19: 予算 | L19: 金額 | M19: 差分 | N19: 予算 | O19: 金額 | P19: 差分
H20: =sumifs($X:$X,$U:$U,F20) -> 0 | L20: =sumifs($X:$X,$S:$S,$L$18,$U:$U,J20) -> 0 | M20: =K20-L20 -> 0 | O20: =sumifs($X:$X,$S:$S,$O$18,$U:$U,J20) -> 0 | P20: =N20-O20 -> 0
H21: =sumifs($X:$X,$U:$U,F21) -> 0 | L21: =sumifs($X:$X,$S:$S,$L$18,$U:$U,J21) -> 0 | M21: =K21-L21 -> 0 | O21: =sumifs($X:$X,$S:$S,$O$18,$U:$U,J21) -> 0 | P21: =N21-O21 -> 0
H22: =sumifs($X:$X,$U:$U,F22) -> 0 | L22: =sumifs($X:$X,$S:$S,$L$18,$U:$U,J22) -> 0 | M22: =K22-L22 -> 0 | O22: =sumifs($X:$X,$S:$S,$O$18,$U:$U,J22) -> 0 | P22: =N22-O22 -> 0
H23: =sumifs($X:$X,$U:$U,F23) -> 0 | L23: =sumifs($X:$X,$S:$S,$L$18,$U:$U,J23) -> 0 | M23: =K23-L23 -> 0 | O23: =sumifs($X:$X,$S:$S,$O$18,$U:$U,J23) -> 0 | P23: =N23-O23 -> 0
H24: =sumifs($X:$X,$U:$U,F24) -> 0 | L24: =sumifs($X:$X,$S:$S,$L$18,$U:$U,J24) -> 0 | M24: =K24-L24 -> 0 | O24: =sumifs($X:$X,$S:$S,$O$18,$U:$U,J24) -> 0 | P24: =N24-O24 -> 0
H25: =sumifs($X:$X,$U:$U,F25) -> 0 | L25: =sumifs($X:$X,$S:$S,$L$18,$U:$U,J25) -> 0 | M25: =K25-L25 -> 0 | O25: =sumifs($X:$X,$S:$S,$O$18,$U:$U,J25) -> 0 | P25: =N25-O25 -> 0
H26: =sumifs($X:$X,$U:$U,F26) -> 0 | L26: =sumifs($X:$X,$S:$S,$L$18,$U:$U,J26) -> 0 | M26: =K26-L26 -> 0 | O26: =sumifs($X:$X,$S:$S,$O$18,$U:$U,J26) -> 0 | P26: =N26-O26 -> 0
H27: =sumifs($X:$X,$U:$U,F27) -> 0 | J27: ALL | K27: =SUM(K20:K26) -> 0 | L27: =SUM(L20:L26) -> 0 | M27: =K27-L27 -> 0 | N27: =SUM(N20:N26) -> 0 | O27: =SUM(O20:O26) -> 0 | P27: =N27-O27 -> 0
H28: =sumifs($X:$X,$U:$U,F28) -> 0
H29: =sumifs($X:$X,$U:$U,F29) -> 0 | J29: 項目 | L29: 3week | O29: 4week
H30: =sumifs($X:$X,$U:$U,F30) -> 0 | K30: 予算 | L30: 金額 | M30: 差分 | N30: 予算 | O30: 金額 | P30: 差分
B31: 合計 | D31: =SUM(D19:D30) -> 0 | F31: 合計 | G31: =SUM(G19:G30) -> 0 | H31: =SUM(H19:H30) -> 0 | L31: =sumifs($X:$X,$S:$S,$L$29,$U:$U,J31) -> 0 | M31: =K31-L31 -> 0 | O31: =sumifs($X:$X,$S:$S,$O$29,$U:$U,J31) -> 0 | P31: =N31-O31 -> 0
L32: =sumifs($X:$X,$S:$S,$L$29,$U:$U,J32) -> 0 | M32: =K32-L32 -> 0 | O32: =sumifs($X:$X,$S:$S,$O$29,$U:$U,J32) -> 0 | P32: =N32-O32 -> 0
B33: 特別費 | F33: 今月の収支 | H33: 金額 | L33: =sumifs($X:$X,$S:$S,$L$29,$U:$U,J33) -> 0 | M33: =K33-L33 -> 0 | O33: =sumifs($X:$X,$S:$S,$O$29,$U:$U,J33) -> 0 | P33: =N33-O33 -> 0
B34: 費目 | C34: 支払方法 | D34: 金額 | F34: 収入（a） | H34: =D14 -> 0 | L34: =sumifs($X:$X,$S:$S,$L$29,$U:$U,J34) -> 0 | M34: =K34-L34 -> 0 | O34: =sumifs($X:$X,$S:$S,$O$29,$U:$U,J34) -> 0 | P34: =N34-O34 -> 0
F35: 先取り貯金・投資（b） | H35: =H14 -> 0 | L35: =sumifs($X:$X,$S:$S,$L$29,$U:$U,J35) -> 0 | M35: =K35-L35 -> 0 | O35: =sumifs($X:$X,$S:$S,$O$29,$U:$U,J35) -> 0 | P35: =N35-O35 -> 0
F36: 支出（c） | H36: =D31+H31 -> 0 | L36: =sumifs($X:$X,$S:$S,$L$29,$U:$U,J36) -> 0 | M36: =K36-L36 -> 0 | O36: =sumifs($X:$X,$S:$S,$O$29,$U:$U,J36) -> 0 | P36: =N36-O36 -> 0
F37: 余り貯金（d）※a-b-c | H37: =H34-H35-H36 -> 0 | L37: =sumifs($X:$X,$S:$S,$L$29,$U:$U,J37) -> 0 | M37: =K37-L37 -> 0 | O37: =sumifs($X:$X,$S:$S,$O$29,$U:$U,J37) -> 0 | P37: =N37-O37 -> 0
F38: 貯蓄合計（e）※b+d | H38: =H35+H37 -> 0 | J38: ALL | K38: =SUM(K31:K37) -> 0 | L38: =SUM(L31:L37) -> 0 | M38: =K38-L38 -> 0 | N38: =SUM(N31:N37) -> 0 | O38: =SUM(O31:O37) -> 0 | P38: =N38-O38 -> 0
F40: 支出率（c/a)×100 | G40: 貯蓄率 （e/a)×100 | J40: 項目 | L40: 5week | O40: ALL
F41: =H36/H34 -> #DIV/0! | G41: =H38/H34 -> #DIV/0! | K41: 予算 | L41: 金額 | M41: 差分 | N41: 予算 | O41: 金額 | P41: 差分
B42: 合計 | D42: =SUM(D35:D41) -> 0 | L42: =sumifs($X:$X,$S:$S,$L$40,$U:$U,J42) -> 0 | M42: =K42-L42 -> 0 | N42: =K20+N20+K31+N31+K42 -> 0 | O42: =L20+O20+L31+O31+L42 -> 0 | P42: =N42-O42 -> 0
D43: ※収支の計算外 | F43: ※目標：80%以下 | H43: ※目標：20%以上 | L43: =sumifs($X:$X,$S:$S,$L$40,$U:$U,J43) -> 0 | M43: =K43-L43 -> 0 | N43: =K21+N21+K32+N32+K43 -> 0 | O43: =L21+O21+L32+O32+L43 -> 0 | P43: =N43-O43 -> 0
...

Sheet 9月
B1: 9 | D1: ← 年・月を変更するとカレンダーが自動更新されます | J1: ※グレーのセルは自動反映します（入力不要）
B2: 2025 | J2: =DATE(B2,B1,1) -> 45901 | R2: 変動費 明細
B4: 収入 | F4: 先取り貯金・投資 | J4: 月 | K4: 火 | L4: 水 | M4: 木 | N4: 金 | O4: 土 | P4: 日 | R4: 日付 | S4: 週 | T4: 支払方法 | U4: 費目 | V4: 詳細 | X4: 金額 | Y4: 満足度
B5: 費目 | C5: 入金口座 | D5: 金額 | F5: 費目 | G5: 支払方法 | H5: 金額 | J5: =$J$2-weekday($J$2)+2 -> 45901 | K5: =J5+1 -> 45902 | L5: =K5+1 -> 45903 | M5: =L5+1 -> 45904 | N5: =M5+1 -> 45905 | O5: =N5+1 -> 45906 | P5: =O5+1 -> 45907 | R5: 45903
J6: =sumifs($X:$X,$R:$R,J5) -> 0 | K6: =sumifs($X:$X,$R:$R,K5) -> 0 | L6: =sumifs($X:$X,$R:$R,L5) -> 0 | M6: =sumifs($X:$X,$R:$R,M5) -> 0 | N6: =sumifs($X:$X,$R:$R,N5) -> 0 | O6: =sumifs($X:$X,$R:$R,O5) -> 0 | P6: =sumifs($X:$X,$R:$R,P5) -> 0
J7: =J5+7 -> 45908 | K7: =K5+7 -> 45909 | L7: =L5+7 -> 45910 | M7: =M5+7 -> 45911 | N7: =N5+7 -> 45912 | O7: =O5+7 -> 45913 | P7: =P5+7 -> 45914
J8: =sumifs($X:$X,$R:$R,J7) -> 0 | K8: =sumifs($X:$X,$R:$R,K7) -> 0 | L8: =sumifs($X:$X,$R:$R,L7) -> 0 | M8: =sumifs($X:$X,$R:$R,M7) -> 0 | N8: =sumifs($X:$X,$R:$R,N7) -> 0 | O8: =sumifs($X:$X,$R:$R,O7) -> 0 | P8: =sumifs($X:$X,$R:$R,P7) -> 0
J9: =J7+7 -> 45915 | K9: =K7+7 -> 45916 | L9: =L7+7 -> 45917 | M9: =M7+7 -> 45918 | N9: =N7+7 -> 45919 | O9: =O7+7 -> 45920 | P9: =P7+7 -> 45921
J10: =sumifs($X:$X,$R:$R,J9) -> 0 | K10: =sumifs($X:$X,$R:$R,K9) -> 0 | L10: =sumifs($X:$X,$R:$R,L9) -> 0 | M10: =sumifs($X:$X,$R:$R,M9) -> 0 | N10: =sumifs($X:$X,$R:$R,N9) -> 0 | O10: =sumifs($X:$X,$R:$R,O9) -> 0 | P10: =sumifs($X:$X,$R:$R,P9) -> 0
J11: =J9+7 -> 45922 | K11: =K9+7 -> 45923 | L11: =L9+7 -> 45924 | M11: =M9+7 -> 45925 | N11: =N9+7 -> 45926 | O11: =O9+7 -> 45927 | P11: =P9+7 -> 45928
J12: =sumifs($X:$X,$R:$R,J11) -> 0 | K12: =sumifs($X:$X,$R:$R,K11) -> 0 | L12: =sumifs($X:$X,$R:$R,L11) -> 0 | M12: =sumifs($X:$X,$R:$R,M11) -> 0 | N12: =sumifs($X:$X,$R:$R,N11) -> 0 | O12: =sumifs($X:$X,$R:$R,O11) -> 0 | P12: =sumifs($X:$X,$R:$R,P11) -> 0
J13: =J11+7 -> 45929 | K13: =K11+7 -> 45930 | L13: =L11+7 -> 45931 | M13: =M11+7 -> 45932 | N13: =N11+7 -> 45933 | O13: =O11+7 -> 45934 | P13: =P11+7 -> 45935
B14: 合計 | D14: =SUM(D6:D13) -> 0 | F14: 合計 | H14: =SUM(H6:H13) -> 0 | J14: =sumifs($X:$X,$R:$R,J13) -> 0 | K14: =sumifs($X:$X,$R:$R,K13) -> 0 | L14: =sumifs($X:$X,$R:$R,L13) -> 0 | M14: =sumifs($X:$X,$R:$R,M13) -> 0 | N14: =sumifs($X:$X,$R:$R,N13) -> 0 | O14: =sumifs($X:$X,$R:$R,O13) -> 0 | P14: =sumifs($X:$X,$R:$R,P13) -> 0
B16: 支出 | F16: 支出 | J16: 週予算 管理
B17: 固定費 | F17: 変動費
B18: 費目 | C18: 支払方法 | D18: 金額 | F18: 費目 | G18: 予算 | H18: 金額 | J18: 項目 | L18: 1week | O18: 2week
H19: =sumifs($X:$X,$U:$U,F19) -> 0 | K19: 予算 | L19: 金額 | M19: 差分 | N19: 予算 | O19: 金額 | P19: 差分
H20: =sumifs($X:$X,$U:$U,F20) -> 0 | L20: =sumifs($X:$X,$S:$S,$L$18,$U:$U,J20) -> 0 | M20: =K20-L20 -> 0 | O20: =sumifs($X:$X,$S:$S,$O$18,$U:$U,J20) -> 0 | P20: =N20-O20 -> 0
H21: =sumifs($X:$X,$U:$U,F21) -> 0 | L21: =sumifs($X:$X,$S:$S,$L$18,$U:$U,J21) -> 0 | M21: =K21-L21 -> 0 | O21: =sumifs($X:$X,$S:$S,$O$18,$U:$U,J21) -> 0 | P21: =N21-O21 -> 0
H22: =sumifs($X:$X,$U:$U,F22) -> 0 | L22: =sumifs($X:$X,$S:$S,$L$18,$U:$U,J22) -> 0 | M22: =K22-L22 -> 0 | O22: =sumifs($X:$X,$S:$S,$O$18,$U:$U,J22) -> 0 | P22: =N22-O22 -> 0
H23: =sumifs($X:$X,$U:$U,F23) -> 0 | L23: =sumifs($X:$X,$S:$S,$L$18,$U:$U,J23) -> 0 | M23: =K23-L23 -> 0 | O23: =sumifs($X:$X,$S:$S,$O$18,$U:$U,J23) -> 0 | P23: =N23-O23 -> 0
H24: =sumifs($X:$X,$U:$U,F24) -> 0 | L24: =sumifs($X:$X,$S:$S,$L$18,$U:$U,J24) -> 0 | M24: =K24-L24 -> 0 | O24: =sumifs($X:$X,$S:$S,$O$18,$U:$U,J24) -> 0 | P24: =N24-O24 -> 0
H25: =sumifs($X:$X,$U:$U,F25) -> 0 | L25: =sumifs($X:$X,$S:$S,$L$18,$U:$U,J25) -> 0 | M25: =K25-L25 -> 0 | O25: =sumifs($X:$X,$S:$S,$O$18,$U:$U,J25) -> 0 | P25: =N25-O25 -> 0
H26: =sumifs($X:$X,$U:$U,F26) -> 0 | L26: =sumifs($X:$X,$S:$S,$L$18,$U:$U,J26) -> 0 | M26: =K26-L26 -> 0 | O26: =sumifs($X:$X,$S:$S,$O$18,$U:$U,J26) -> 0 | P26: =N26-O26 -> 0
H27: =sumifs($X:$X,$U:$U,F27) -> 0 | J27: ALL | K27: =SUM(K20:K26) -> 0 | L27: =SUM(L20:L26) -> 0 | M27: =K27-L27 -> 0 | N27: =SUM(N20:N26) -> 0 | O27: =SUM(O20:O26) -> 0 | P27: =N27-O27 -> 0
H28: =sumifs($X:$X,$U:$U,F28) -> 0
H29: =sumifs($X:$X,$U:$U,F29) -> 0 | J29: 項目 | L29: 3week | O29: 4week
H30: =sumifs($X:$X,$U:$U,F30) -> 0 | K30: 予算 | L30: 金額 | M30: 差分 | N30: 予算 | O30: 金額 | P30: 差分
B31: 合計 | D31: =SUM(D19:D30) -> 0 | F31: 合計 | G31: =SUM(G19:G30) -> 0 | H31: =SUM(H19:H30) -> 0 | L31: =sumifs($X:$X,$S:$S,$L$29,$U:$U,J31) -> 0 | M31: =K31-L31 -> 0 | O31: =sumifs($X:$X,$S:$S,$O$29,$U:$U,J31) -> 0 | P31: =N31-O31 -> 0
L32: =sumifs($X:$X,$S:$S,$L$29,$U:$U,J32) -> 0 | M32: =K32-L32 -> 0 | O32: =sumifs($X:$X,$S:$S,$O$29,$U:$U,J32) -> 0 | P32: =N32-O32 -> 0
B33: 特別費 | F33: 今月の収支 | H33: 金額 | L33: =sumifs($X:$X,$S:$S,$L$29,$U:$U,J33) -> 0 | M33: =K33-L33 -> 0 | O33: =sumifs($X:$X,$S:$S,$O$29,$U:$U,J33) -> 0 | P33: =N33-O33 -> 0
B34: 費目 | C34: 支払方法 | D34: 金額 | F34: 収入（a） | H34: =D14 -> 0 | L34: =sumifs($X:$X,$S:$S,$L$29,$U:$U,J34) -> 0 | M34: =K34-L34 -> 0 | O34: =sumifs($X:$X,$S:$S,$O$29,$U:$U,J34) -> 0 | P34: =N34-O34 -> 0
F35: 先取り貯金・投資（b） | H35: =H14 -> 0 | L35: =sumifs($X:$X,$S:$S,$L$29,$U:$U,J35) -> 0 | M35: =K35-L35 -> 0 | O35: =sumifs($X:$X,$S:$S,$O$29,$U:$U,J35) -> 0 | P35: =N35-O35 -> 0
F36: 支出（c） | H36: =D31+H31 -> 0 | L36: =sumifs($X:$X,$S:$S,$L$29,$U:$U,J36) -> 0 | M36: =K36-L36 -> 0 | O36: =sumifs($X:$X,$S:$S,$O$29,$U:$U,J36) -> 0 | P36: =N36-O36 -> 0
F37: 余り貯金（d）※a-b-c | H37: =H34-H35-H36 -> 0 | L37: =sumifs($X:$X,$S:$S,$L$29,$U:$U,J37) -> 0 | M37: =K37-L37 -> 0 | O37: =sumifs($X:$X,$S:$S,$O$29,$U:$U,J37) -> 0 | P37: =N37-O37 -> 0
F38: 貯蓄合計（e）※b+d | H38: =H35+H37 -> 0 | J38: ALL | K38: =SUM(K31:K37) -> 0 | L38: =SUM(L31:L37) -> 0 | M38: =K38-L38 -> 0 | N38: =SUM(N31:N37) -> 0 | O38: =SUM(O31:O37) -> 0 | P38: =N38-O38 -> 0
F40: 支出率（c/a)×100 | G40: 貯蓄率 （e/a)×100 | J40: 項目 | L40: 5week | O40: ALL
F41: =H36/H34 -> #DIV/0! | G41: =H38/H34 -> #DIV/0! | K41: 予算 | L41: 金額 | M41: 差分 | N41: 予算 | O41: 金額 | P41: 差分
B42: 合計 | D42: =SUM(D35:D41) -> 0 | L42: =sumifs($X:$X,$S:$S,$L$40,$U:$U,J42) -> 0 | M42: =K42-L42 -> 0 | N42: =K20+N20+K31+N31+K42 -> 0 | O42: =L20+O20+L31+O31+L42 -> 0 | P42: =N42-O42 -> 0
D43: ※収支の計算外 | F43: ※目標：80%以下 | H43: ※目標：20%以上 | L43: =sumifs($X:$X,$S:$S,$L$40,$U:$U,J43) -> 0 | M43: =K43-L43 -> 0 | N43: =K21+N21+K32+N32+K43 -> 0 | O43: =L21+O21+L32+O32+L43 -> 0 | P43: =N43-O43 -> 0
...

Sheet 10月
B1: 10 | D1: ← 年・月を変更するとカレンダーが自動更新されます | J1: ※グレーのセルは自動反映します（入力不要）
B2: 2025 | J2: =DATE(B2,B1,1) -> 45931 | R2: 変動費 明細
